Workbook

Sheet 使い方
B1: 職人スケジュール管理表（石善建設）
B2: 入力するのは「案件台帳」シートだけ。ほかの3シートは全部自動計算です。
B4: ■ シートの構成
B5: ① 案件台帳（入力） | C5: 唯一の入力シート。1行＝1職人×1案件。物件名・職人・開始日・終了予定日を入れるだけ。黄色セルが入力欄。
B6: ② 職人ダッシュボード | C6: 職人ごとに「今の仕事（開始日・終了予定日・工期日数・残り日数）」「次の仕事」「次の仕事までの空き日数」を自動表示。
B7: ③ 配置検討 | C7: 次に受ける仕事の希望開始日と工期を入れると、誰が空いていて誰を配置すべきか（◎△×・推奨順位）を自動判定。
B8: ④ 稼働カレンダー | C8: 基準日から63日分の稼働／空きを職人×日付のマス目で表示。青＝稼働、黄＝空き。
B10: ■ 使う手順
B11: 手順1 | C11: 「案件台帳」に、いま動いている現場と、決まっている次の現場を職人ごとに1行ずつ入力する（過去の完了案件も残しておくと空き期間が正しく出ます）。
B12: 手順2 | C12: 「職人ダッシュボード」を見る。アラート欄が⚠の職人が、手当てが必要な職人。
B13: 手順3 | C13: 新しい引き合いが来たら「配置検討」の黄色セルに希望開始日と必要工期を入れ、判定◎かつ推奨順位1位の職人を候補にする。
B14: 手順4 | C14: 決まったら「案件台帳」に1行追加する。ダッシュボードとカレンダーは自動で更新される。
B16: ■ 用語の定義
B17: 基準日 | C17: 「案件台帳」B3。=TODAY() が入っているので開くたび今日の日付になります。将来の日付でシミュレーションしたい時は、日付を直接打ち込んで上書きしてください。
B18: 工期日数 | C18: 終了予定日 − 開始日 ＋ 1（初日と最終日を両方数えた日数）。
B19: 経過日数 | C19: 基準日 − 開始日 ＋ 1。今の現場に何日入っているか。
B20: 残り日数 | C20: 終了予定日 − 基準日。今の現場があと何日残っているか。
B21: 空き開始日 | C21: 稼働中なら「今の現場の終了予定日＋1」、空き中なら「直前に終わった現場の終了日＋1」。手が空く日。
B22: 次の仕事までの空き日数 | C22: 次回開始日 − 空き開始日。現場と現場のあいだが何日空くか（0＝連続、マイナス＝重複）。
B23: 本日以降の空き日数 | C23: 基準日から次回開始日までの空き日数。すでに空いている職人の「あと何日空いているか」。
B25: ■ アラートの意味（職人ダッシュボード 最終列）
B26: ⚠ 重複配置 | C26: 同じ日に2件以上の現場が重なっている。台帳を確認。
B27: ⚠ 終了予定日が未入力 | C27: 終了日が空欄の案件があるため、空き日数もカレンダーも正しく出ない。最優先で埋める。
B28: ⚠ 次の仕事が未定 | C28: 次の現場が台帳にない。営業・見積を前倒しで動かす。
B29: ⚠ 空き◯日 | C29: 7日以上の空きがある。短工期の仕事（改修・メンテ）を差し込む検討を。
B30: 連続稼働（余裕なし） | C30: 空き0日。段取り・材料手配・天候遅延の余裕がないので注意。
B32: ■ いま埋まっていないデータ（元ファイル「①シンプル型」の時点で空欄だったもの）
B33: 松田 | C33: 一条（菅野様邸）の開始日が未入力。
B34: 重田・田中 | C34: 三栄港運（潮見）の終了予定日が未入力。前案件の物件名・開始日も未記載。
B35: 多田・松田・原田 | C35: 次案件の物件名と終了予定日が未入力（開始予定日のみ判明）。
C36: ※ この4件は元データに無かったため空欄のままにしています。推測で日付は入れていません。埋めるとダッシュボードとカレンダーが完成します。
B38: ■ 元データの出典
C39: 職人名・物件名・日付は、アップロードされた「職人5人スケジュール3パターン」の「①シンプル型」シートの内容をそのまま転記したものです。②③シートのサンプル（大工A〜E／A様邸〜O様邸）は実データではないため取り込んでいません。

Sheet 案件台帳
A1: ① 案件台帳（このシートだけ入力します）
A2: 1行＝1職人×1案件。完了した案件も消さずに残すと、次の仕事までの空き日数が正しく計算されます。黄色＝入力欄／灰色＝自動計算（触らない）。
A3: 基準日（今日） | B3: =TODAY() | C3: ← すべての判定（施工中／空き／空き日数）はこの日を基準に計算します
A5: No | B5: 物件名 | C5: 職人 | D5: 工程 | E5: 開始日 | F5: 終了予定日 | G5: 状況 | H5: 工期日数 | I5: 備考 | J5: 自動:現在 | K5: 自動:次案件 | L5: 自動:直前完了
A6: 1 | B6: 一条（菅野様邸） | C6: 多田 | E6: 46226 | F6: 46262 | G6: =IF($C6="","",IF(AND($E6<>"",$E6>$B$3),"予定",IF($F6="","要確認（終了日未入力）",IF($F6<$B$3,"完了","施工中")))) | H6: =IF(OR($E6="",$F6=""),"",$F6-$E6+1) | I6: 元表①より | J6: =IF($C6="","",IF(AND($F6<>"",$F6>=$B$3,$E6<=$B$3),$C6,"")) | K6: =IF($C6="","",IF(AND($E6<>"",$E6>$B$3,COUNTIFS($C$6:$C$65,$C6,$E$6:$E$65,">"&$B$3,$E$6:$E$65,"<"&$E6)=0),$C6,"")) | L6: =IF($C6="","",IF(AND($F6<>"",$F6<$B$3,COUNTIFS($C$6:$C$65,$C6,$F$6:$F$65,"<"&$B$3,$F$6:$F$65,">"&$F6)=0),$C6,""))
A7: 2 | B7: （次案件・物件名未定） | C7: 多田 | E7: 46279 | G7: =IF($C7="","",IF(AND($E7<>"",$E7>$B$3),"予定",IF($F7="","要確認（終了日未入力）",IF($F7<$B$3,"完了","施工中")))) | H7: =IF(OR($E7="",$F7=""),"",$F7-$E7+1) | I7: 開始予定のみ判明。物件名と終了予定日を入力してください | J7: =IF($C7="","",IF(AND($F7<>"",$F7>=$B$3,$E7<=$B$3),$C7,"")) | K7: =IF($C7="","",IF(AND($E7<>"",$E7>$B$3,COUNTIFS($C$6:$C$65,$C7,$E$6:$E$65,">"&$B$3,$E$6:$E$65,"<"&$E7)=0),$C7,"")) | L7: =IF($C7="","",IF(AND($F7<>"",$F7<$B$3,COUNTIFS($C$6:$C$65,$C7,$F$6:$F$65,"<"&$B$3,$F$6:$F$65,">"&$F7)=0),$C7,""))
A8: 3 | B8: 一条（菅野様邸） | C8: 松田 | F8: 46262 | G8: =IF($C8="","",IF(AND($E8<>"",$E8>$B$3),"予定",IF($F8="","要確認（終了日未入力）",IF($F8<$B$3,"完了","施工中")))) | H8: =IF(OR($E8="",$F8=""),"",$F8-$E8+1) | I8: 開始日が未入力（元表①も空欄） | J8: =IF($C8="","",IF(AND($F8<>"",$F8>=$B$3,$E8<=$B$3),$C8,"")) | K8: =IF($C8="","",IF(AND($E8<>"",$E8>$B$3,COUNTIFS($C$6:$C$65,$C8,$E$6:$E$65,">"&$B$3,$E$6:$E$65,"<"&$E8)=0),$C8,"")) | L8: =IF($C8="","",IF(AND($F8<>"",$F8<$B$3,COUNTIFS($C$6:$C$65,$C8,$F$6:$F$65,"<"&$B$3,$F$6:$F$65,">"&$F8)=0),$C8,""))
A9: 4 | B9: （次案件・物件名未定） | C9: 松田 | E9: 46286 | G9: =IF($C9="","",IF(AND($E9<>"",$E9>$B$3),"予定",IF($F9="","要確認（終了日未入力）",IF($F9<$B$3,"完了","施工中")))) | H9: =IF(OR($E9="",$F9=""),"",$F9-$E9+1) | I9: 開始予定のみ判明。物件名と終了予定日を入力してください | J9: =IF($C9="","",IF(AND($F9<>"",$F9>=$B$3,$E9<=$B$3),$C9,"")) | K9: =IF($C9="","",IF(AND($E9<>"",$E9>$B$3,COUNTIFS($C$6:$C$65,$C9,$E$6:$E$65,">"&$B$3,$E$6:$E$65,"<"&$E9)=0),$C9,"")) | L9: =IF($C9="","",IF(AND($F9<>"",$F9<$B$3,COUNTIFS($C$6:$C$65,$C9,$F$6:$F$65,"<"&$B$3,$F$6:$F$65,">"&$F9)=0),$C9,""))
A10: 5 | B10: （前案件・物件名未記載） | C10: 重田 | F10: 46223 | G10: =IF($C10="","",IF(AND($E10<>"",$E10>$B$3),"予定",IF($F10="","要確認（終了日未入力）",IF($F10<$B$3,"完了","施工中")))) | H10: =IF(OR($E10="",$F10=""),"",$F10-$E10+1) | I10: 元表①では終了日のみ記載 | J10: =IF($C10="","",IF(AND($F10<>"",$F10>=$B$3,$E10<=$B$3),$C10,"")) | K10: =IF($C10="","",IF(AND($E10<>"",$E10>$B$3,COUNTIFS($C$6:$C$65,$C10,$E$6:$E$65,">"&$B$3,$E$6:$E$65,"<"&$E10)=0),$C10,"")) | L10: =IF($C10="","",IF(AND($F10<>"",$F10<$B$3,COUNTIFS($C$6:$C$65,$C10,$F$6:$F$65,"<"&$B$3,$F$6:$F$65,">"&$F10)=0),$C10,""))
A11: 6 | B11: 三栄港運（潮見） | C11: 重田 | E11: 46259 | G11: =IF($C11="","",IF(AND($E11<>"",$E11>$B$3),"予定",IF($F11="","要確認（終了日未入力）",IF($F11<$B$3,"完了","施工中")))) | H11: =IF(OR($E11="",$F11=""),"",$F11-$E11+1) | I11: 終了予定日を入力してください | J11: =IF($C11="","",IF(AND($F11<>"",$F11>=$B$3,$E11<=$B$3),$C11,"")) | K11: =IF($C11="","",IF(AND($E11<>"",$E11>$B$3,COUNTIFS($C$6:$C$65,$C11,$E$6:$E$65,">"&$B$3,$E$6:$E$65,"<"&$E11)=0),$C11,"")) | L11: =IF($C11="","",IF(AND($F11<>"",$F11<$B$3,COUNTIFS($C$6:$C$65,$C11,$F$6:$F$65,"<"&$B$3,$F$6:$F$65,">"&$F11)=0),$C11,""))
A12: 7 | B12: 垣内邸 | C12: 原田 | E12: 46219 | F12: 46281 | G12: =IF($C12="","",IF(AND($E12<>"",$E12>$B$3),"予定",IF($F12="","要確認（終了日未入力）",IF($F12<$B$3,"完了","施工中")))) | H12: =IF(OR($E12="",$F12=""),"",$F12-$E12+1) | I12: 元表①より | J12: =IF($C12="","",IF(AND($F12<>"",$F12>=$B$3,$E12<=$B$3),$C12,"")) | K12: =IF($C12="","",IF(AND($E12<>"",$E12>$B$3,COUNTIFS($C$6:$C$65,$C12,$E$6:$E$65,">"&$B$3,$E$6:$E$65,"<"&$E12)=0),$C12,"")) | L12: =IF($C12="","",IF(AND($F12<>"",$F12<$B$3,COUNTIFS($C$6:$C$65,$C12,$F$6:$F$65,"<"&$B$3,$F$6:$F$65,">"&$F12)=0),$C12,""))
A13: 8 | B13: （次案件・物件名未定） | C13: 原田 | E13: 46282 | G13: =IF($C13="","",IF(AND($E13<>"",$E13>$B$3),"予定",IF($F13="","要確認（終了日未入力）",IF($F13<$B$3,"完了","施工中")))) | H13: =IF(OR($E13="",$F13=""),"",$F13-$E13+1) | I13: 開始予定のみ判明。物件名と終了予定日を入力してください | J13: =IF($C13="","",IF(AND($F13<>"",$F13>=$B$3,$E13<=$B$3),$C13,"")) | K13: =IF($C13="","",IF(AND($E13<>"",$E13>$B$3,COUNTIFS($C$6:$C$65,$C13,$E$6:$E$65,">"&$B$3,$E$6:$E$65,"<"&$E13)=0),$C13,"")) | L13: =IF($C13="","",IF(AND($F13<>"",$F13<$B$3,COUNTIFS($C$6:$C$65,$C13,$F$6:$F$65,"<"&$B$3,$F$6:$F$65,">"&$F13)=0),$C13,""))
A14: 9 | B14: （前案件・物件名未記載） | C14: 田中 | F14: 46230 | G14: =IF($C14="","",IF(AND($E14<>"",$E14>$B$3),"予定",IF($F14="","要確認（終了日未入力）",IF($F14<$B$3,"完了","施工中")))) | H14: =IF(OR($E14="",$F14=""),"",$F14-$E14+1) | I14: 元表①では終了日のみ記載 | J14: =IF($C14="","",IF(AND($F14<>"",$F14>=$B$3,$E14<=$B$3),$C14,"")) | K14: =IF($C14="","",IF(AND($E14<>"",$E14>$B$3,COUNTIFS($C$6:$C$65,$C14,$E$6:$E$65,">"&$B$3,$E$6:$E$65,"<"&$E14)=0),$C14,"")) | L14: =IF($C14="","",IF(AND($F14<>"",$F14<$B$3,COUNTIFS($C$6:$C$65,$C14,$F$6:$F$65,"<"&$B$3,$F$6:$F$65,">"&$F14)=0),$C14,""))
A15: 10 | B15: 三栄港運（潮見） | C15: 田中 | E15: 46259 | G15: =IF($C15="","",IF(AND($E15<>"",$E15>$B$3),"予定",IF($F15="","要確認（終了日未入力）",IF($F15<$B$3,"完了","施工中")))) | H15: =IF(OR($E15="",$F15=""),"",$F15-$E15+1) | I15: 終了予定日を入力してください | J15: =IF($C15="","",IF(AND($F15<>"",$F15>=$B$3,$E15<=$B$3),$C15,"")) | K15: =IF($C15="","",IF(AND($E15<>"",$E15>$B$3,COUNTIFS($C$6:$C$65,$C15,$E$6:$E$65,">"&$B$3,$E$6:$E$65,"<"&$E15)=0),$C15,"")) | L15: =IF($C15="","",IF(AND($F15<>"",$F15<$B$3,COUNTIFS($C$6:$C$65,$C15,$F$6:$F$65,"<"&$B$3,$F$6:$F$65,">"&$F15)=0),$C15,""))
A16: 11 | G16: =IF($C16="","",IF(AND($E16<>"",$E16>$B$3),"予定",IF($F16="","要確認（終了日未入力）",IF($F16<$B$3,"完了","施工中")))) | H16: =IF(OR($E16="",$F16=""),"",$F16-$E16+1) | J16: =IF($C16="","",IF(AND($F16<>"",$F16>=$B$3,$E16<=$B$3),$C16,"")) | K16: =IF($C16="","",IF(AND($E16<>"",$E16>$B$3,COUNTIFS($C$6:$C$65,$C16,$E$6:$E$65,">"&$B$3,$E$6:$E$65,"<"&$E16)=0),$C16,"")) | L16: =IF($C16="","",IF(AND($F16<>"",$F16<$B$3,COUNTIFS($C$6:$C$65,$C16,$F$6:$F$65,"<"&$B$3,$F$6:$F$65,">"&$F16)=0),$C16,""))
A17: 12 | G17: =IF($C17="","",IF(AND($E17<>"",$E17>$B$3),"予定",IF($F17="","要確認（終了日未入力）",IF($F17<$B$3,"完了","施工中")))) | H17: =IF(OR($E17="",$F17=""),"",$F17-$E17+1) | J17: =IF($C17="","",IF(AND($F17<>"",$F17>=$B$3,$E17<=$B$3),$C17,"")) | K17: =IF($C17="","",IF(AND($E17<>"",$E17>$B$3,COUNTIFS($C$6:$C$65,$C17,$E$6:$E$65,">"&$B$3,$E$6:$E$65,"<"&$E17)=0),$C17,"")) | L17: =IF($C17="","",IF(AND($F17<>"",$F17<$B$3,COUNTIFS($C$6:$C$65,$C17,$F$6:$F$65,"<"&$B$3,$F$6:$F$65,">"&$F17)=0),$C17,""))
A18: 13 | G18: =IF($C18="","",IF(AND($E18<>"",$E18>$B$3),"予定",IF($F18="","要確認（終了日未入力）",IF($F18<$B$3,"完了","施工中")))) | H18: =IF(OR($E18="",$F18=""),"",$F18-$E18+1) | J18: =IF($C18="","",IF(AND($F18<>"",$F18>=$B$3,$E18<=$B$3),$C18,"")) | K18: =IF($C18="","",IF(AND($E18<>"",$E18>$B$3,COUNTIFS($C$6:$C$65,$C18,$E$6:$E$65,">"&$B$3,$E$6:$E$65,"<"&$E18)=0),$C18,"")) | L18: =IF($C18="","",IF(AND($F18<>"",$F18<$B$3,COUNTIFS($C$6:$C$65,$C18,$F$6:$F$65,"<"&$B$3,$F$6:$F$65,">"&$F18)=0),$C18,""))
A19: 14 | G19: =IF($C19="","",IF(AND($E19<>"",$E19>$B$3),"予定",IF($F19="","要確認（終了日未入力）",IF($F19<$B$3,"完了","施工中")))) | H19: =IF(OR($E19="",$F19=""),"",$F19-$E19+1) | J19: =IF($C19="","",IF(AND($F19<>"",$F19>=$B$3,$E19<=$B$3),$C19,"")) | K19: =IF($C19="","",IF(AND($E19<>"",$E19>$B$3,COUNTIFS($C$6:$C$65,$C19,$E$6:$E$65,">"&$B$3,$E$6:$E$65,"<"&$E19)=0),$C19,"")) | L19: =IF($C19="","",IF(AND($F19<>"",$F19<$B$3,COUNTIFS($C$6:$C$65,$C19,$F$6:$F$65,"<"&$B$3,$F$6:$F$65,">"&$F19)=0),$C19,""))
A20: 15 | G20: =IF($C20="","",IF(AND($E20<>"",$E20>$B$3),"予定",IF($F20="","要確認（終了日未入力）",IF($F20<$B$3,"完了","施工中")))) | H20: =IF(OR($E20="",$F20=""),"",$F20-$E20+1) | J20: =IF($C20="","",IF(AND($F20<>"",$F20>=$B$3,$E20<=$B$3),$C20,"")) | K20: =IF($C20="","",IF(AND($E20<>"",$E20>$B$3,COUNTIFS($C$6:$C$65,$C20,$E$6:$E$65,">"&$B$3,$E$6:$E$65,"<"&$E20)=0),$C20,"")) | L20: =IF($C20="","",IF(AND($F20<>"",$F20<$B$3,COUNTIFS($C$6:$C$65,$C20,$F$6:$F$65,"<"&$B$3,$F$6:$F$65,">"&$F20)=0),$C20,""))
A21: 16 | G21: =IF($C21="","",IF(AND($E21<>"",$E21>$B$3),"予定",IF($F21="","要確認（終了日未入力）",IF($F21<$B$3,"完了","施工中")))) | H21: =IF(OR($E21="",$F21=""),"",$F21-$E21+1) | J21: =IF($C21="","",IF(AND($F21<>"",$F21>=$B$3,$E21<=$B$3),$C21,"")) | K21: =IF($C21="","",IF(AND($E21<>"",$E21>$B$3,COUNTIFS($C$6:$C$65,$C21,$E$6:$E$65,">"&$B$3,$E$6:$E$65,"<"&$E21)=0),$C21,"")) | L21: =IF($C21="","",IF(AND($F21<>"",$F21<$B$3,COUNTIFS($C$6:$C$65,$C21,$F$6:$F$65,"<"&$B$3,$F$6:$F$65,">"&$F21)=0),$C21,""))
A22: 17 | G22: =IF($C22="","",IF(AND($E22<>"",$E22>$B$3),"予定",IF($F22="","要確認（終了日未入力）",IF($F22<$B$3,"完了","施工中")))) | H22: =IF(OR($E22="",$F22=""),"",$F22-$E22+1) | J22: =IF($C22="","",IF(AND($F22<>"",$F22>=$B$3,$E22<=$B$3),$C22,"")) | K22: =IF($C22="","",IF(AND($E22<>"",$E22>$B$3,COUNTIFS($C$6:$C$65,$C22,$E$6:$E$65,">"&$B$3,$E$6:$E$65,"<"&$E22)=0),$C22,"")) | L22: =IF($C22="","",IF(AND($F22<>"",$F22<$B$3,COUNTIFS($C$6:$C$65,$C22,$F$6:$F$65,"<"&$B$3,$F$6:$F$65,">"&$F22)=0),$C22,""))
A23: 18 | G23: =IF($C23="","",IF(AND($E23<>"",$E23>$B$3),"予定",IF($F23="","要確認（終了日未入力）",IF($F23<$B$3,"完了","施工中")))) | H23: =IF(OR($E23="",$F23=""),"",$F23-$E23+1) | J23: =IF($C23="","",IF(AND($F23<>"",$F23>=$B$3,$E23<=$B$3),$C23,"")) | K23: =IF($C23="","",IF(AND($E23<>"",$E23>$B$3,COUNTIFS($C$6:$C$65,$C23,$E$6:$E$65,">"&$B$3,$E$6:$E$65,"<"&$E23)=0),$C23,"")) | L23: =IF($C23="","",IF(AND($F23<>"",$F23<$B$3,COUNTIFS($C$6:$C$65,$C23,$F$6:$F$65,"<"&$B$3,$F$6:$F$65,">"&$F23)=0),$C23,""))
A24: 19 | G24: =IF($C24="","",IF(AND($E24<>"",$E24>$B$3),"予定",IF($F24="","要確認（終了日未入力）",IF($F24<$B$3,"完了","施工中")))) | H24: =IF(OR($E24="",$F24=""),"",$F24-$E24+1) | J24: =IF($C24="","",IF(AND($F24<>"",$F24>=$B$3,$E24<=$B$3),$C24,"")) | K24: =IF($C24="","",IF(AND($E24<>"",$E24>$B$3,COUNTIFS($C$6:$C$65,$C24,$E$6:$E$65,">"&$B$3,$E$6:$E$65,"<"&$E24)=0),$C24,"")) | L24: =IF($C24="","",IF(AND($F24<>"",$F24<$B$3,COUNTIFS($C$6:$C$65,$C24,$F$6:$F$65,"<"&$B$3,$F$6:$F$65,">"&$F24)=0),$C24,""))
A25: 20 | G25: =IF($C25="","",IF(AND($E25<>"",$E25>$B$3),"予定",IF($F25="","要確認（終了日未入力）",IF($F25<$B$3,"完了","施工中")))) | H25: =IF(OR($E25="",$F25=""),"",$F25-$E25+1) | J25: =IF($C25="","",IF(AND($F25<>"",$F25>=$B$3,$E25<=$B$3),$C25,"")) | K25: =IF($C25="","",IF(AND($E25<>"",$E25>$B$3,COUNTIFS($C$6:$C$65,$C25,$E$6:$E$65,">"&$B$3,$E$6:$E$65,"<"&$E25)=0),$C25,"")) | L25: =IF($C25="","",IF(AND($F25<>"",$F25<$B$3,COUNTIFS($C$6:$C$65,$C25,$F$6:$F$65,"<"&$B$3,$F$6:$F$65,">"&$F25)=0),$C25,""))
A26: 21 | G26: =IF($C26="","",IF(AND($E26<>"",$E26>$B$3),"予定",IF($F26="","要確認（終了日未入力）",IF($F26<$B$3,"完了","施工中")))) | H26: =IF(OR($E26="",$F26=""),"",$F26-$E26+1) | J26: =IF($C26="","",IF(AND($F26<>"",$F26>=$B$3,$E26<=$B$3),$C26,"")) | K26: =IF($C26="","",IF(AND($E26<>"",$E26>$B$3,COUNTIFS($C$6:$C$65,$C26,$E$6:$E$65,">"&$B$3,$E$6:$E$65,"<"&$E26)=0),$C26,"")) | L26: =IF($C26="","",IF(AND($F26<>"",$F26<$B$3,COUNTIFS($C$6:$C$65,$C26,$F$6:$F$65,"<"&$B$3,$F$6:$F$65,">"&$F26)=0),$C26,""))
A27: 22 | G27: =IF($C27="","",IF(AND($E27<>"",$E27>$B$3),"予定",IF($F27="","要確認（終了日未入力）",IF($F27<$B$3,"完了","施工中")))) | H27: =IF(OR($E27="",$F27=""),"",$F27-$E27+1) | J27: =IF($C27="","",IF(AND($F27<>"",$F27>=$B$3,$E27<=$B$3),$C27,"")) | K27: =IF($C27="","",IF(AND($E27<>"",$E27>$B$3,COUNTIFS($C$6:$C$65,$C27,$E$6:$E$65,">"&$B$3,$E$6:$E$65,"<"&$E27)=0),$C27,"")) | L27: =IF($C27="","",IF(AND($F27<>"",$F27<$B$3,COUNTIFS($C$6:$C$65,$C27,$F$6:$F$65,"<"&$B$3,$F$6:$F$65,">"&$F27)=0),$C27,""))
... A65: 60 | G65: =IF($C65="","",IF(AND($E65<>"",$E65>$B$3),"予定",IF($F65="","要確認（終了日未入力）",IF($F65<$B$3,"完了","施工中")))) | H65: =IF(OR($E65="",$F65=""),"",$F65-$E65+1) | J65: =IF($C65="","",IF(AND($F65<>"",$F65>=$B$3,$E65<=$B$3),$C65,"")) | K65: =IF($C65="","",IF(AND($E65<>"",$E65>$B$3,COUNTIFS($C$6:$C$65,$C65,$E$6:$E$65,">"&$B$3,$E$6:$E$65,"<"&$E65)=0),$C65,"")) | L65: =IF($C65="","",IF(AND($F65<>"",$F65<$B$3,COUNTIFS($C$6:$C$65,$C65,$F$6:$F$65,"<"&$B$3,$F$6:$F$65,">"&$F65)=0),$C65,""))

Sheet 職人ダッシュボード
A1: ② 職人ダッシュボード（案件台帳から自動計算）
A2: 青字＝手入力（職人名のみ）。それ以外はすべて自動。基準日： | E2: ='案件台帳'!$B$3
A4: 職人 | B4: 状態 | C4: 現在の案件 | D4: 工程 | E4: 開始日 | F4: 終了予定日 | G4: 工期日数 | H4: 経過日数 | I4: 残り日数 | J4: 空き開始日 | K4: 次の案件 | L4: 次回開始日 | M4: 次の仕事までの 空き日数 | N4: 本日以降の 空き日数 | O4: 登録済み 総稼働日数 | P4: アラート
A5: 多田 | B5: =IF($A5="","",IF(COUNTIF('案件台帳'!$J$6:$J$65,$A5)>0,"稼働中","空き中")) | C5: =IF($A5="","",IFERROR(IF(INDEX('案件台帳'!$B$6:$B$65,MATCH($A5,'案件台帳'!$J$6:$J$65,0))="","",INDEX('案件台帳'!$B$6:$B$65,MATCH($A5,'案件台帳'!$J$6:$J$65,0))),"―（現在は空き）")) | D5: =IF($A5="","",IFERROR(IF(INDEX('案件台帳'!$D$6:$D$65,MATCH($A5,'案件台帳'!$J$6:$J$65,0))="","",INDEX('案件台帳'!$D$6:$D$65,MATCH($A5,'案件台帳'!$J$6:$J$65,0))),"")) | E5: =IF($A5="","",IFERROR(IF(INDEX('案件台帳'!$E$6:$E$65,MATCH($A5,'案件台帳'!$J$6:$J$65,0))="","",INDEX('案件台帳'!$E$6:$E$65,MATCH($A5,'案件台帳'!$J$6:$J$65,0))),"")) | F5: =IF($A5="","",IFERROR(IF(INDEX('案件台帳'!$F$6:$F$65,MATCH($A5,'案件台帳'!$J$6:$J$65,0))="","",INDEX('案件台帳'!$F$6:$F$65,MATCH($A5,'案件台帳'!$J$6:$J$65,0))),"")) | G5: =IF(OR($E5="",$F5=""),"",$F5-$E5+1) | H5: =IF($E5="","",'案件台帳'!$B$3-$E5+1) | I5: =IF($F5="","",$F5-'案件台帳'!$B$3) | J5: =IF($A5="","",IF($B5="稼働中",IF($F5="","",$F5+1),IFERROR(IF(INDEX('案件台帳'!$F$6:$F$65,MATCH($A5,'案件台帳'!$L$6:$L$65,0))="","",INDEX('案件台帳'!$F$6:$F$65,MATCH($A5,'案件台帳'!$L$6:$L$65,0))+1),'案件台帳'!$B$3))) | K5: =IF($A5="","",IFERROR(IF(INDEX('案件台帳'!$B$6:$B$65,MATCH($A5,'案件台帳'!$K$6:$K$65,0))="","",INDEX('案件台帳'!$B$6:$B$65,MATCH($A5,'案件台帳'!$K$6:$K$65,0))),"未定")) | L5: =IF($A5="","",IFERROR(IF(INDEX('案件台帳'!$E$6:$E$65,MATCH($A5,'案件台帳'!$K$6:$K$65,0))="","",INDEX('案件台帳'!$E$6:$E$65,MATCH($A5,'案件台帳'!$K$6:$K$65,0))),"")) | M5: =IF(OR($L5="",$J5=""),"",$L5-$J5) | N5: =IF($L5="","",MAX(0,$L5-MAX('案件台帳'!$B$3,$J5))) | O5: =IF($A5="","",SUMIF('案件台帳'!$C$6:$C$65,$A5,'案件台帳'!$H$6:$H$65)) | P5: =IF($A5="","",IF(TRIM(IF(COUNTIFS('案件台帳'!$C$6:$C$65,$A5,'案件台帳'!$E$6:$E$65,"<="&'案件台帳'!$B$3,'案件台帳'!$F$6:$F$65,">="&'案件台帳'!$B$3)>1,"⚠ 重複配置 ","")&IF(COUNTIFS('案件台帳'!$C$6:$C$65,$A5)-COUNTIFS('案件台帳'!$C$6:$C$65,$A5,'案件台帳'!$F$6:$F$65,">0")>0,"⚠ 終了予定日が未入力 ","")&IF($K5="未定","⚠ 次の仕事が未定：営業・見積を前倒し",IF($M5="","",IF($M5<0,"⚠ 前現場と"&ABS($M5)&"日重複",IF($M5=0,"連続稼働（余裕なし）",IF($M5>=7,"⚠ 空き"&$M5&"日：短工期案件の差し込み検討","空き"&$M5&"日"))))))="","OK",TRIM(IF(COUNTIFS('案件台帳'!$C$6:$C$65,$A5,'案件台帳'!$E$6:$E$65,"<="&'案件台帳'!$B$3,'案件台帳'!$F$6:$F$65,">="&'案件台帳'!$B$3)>1,"⚠ 重複配置 ","")&IF(COUNTIFS('案件台帳'!$C$6:$C$65,$A5)-COUNTIFS('案件台帳'!$C$6:$C$65,$A5,'案件台帳'!$F$6:$F$65,">0")>0,"⚠ 終了予定日が未入力 ","")&IF($K5="未定","⚠ 次の仕事が未定：営業・見積を前倒し",IF($M5="","",IF($M5<0,"⚠ 前現場と"&ABS($M5)&"日重複",IF($M5=0,"連続稼働（余裕なし）",IF($M5>=7,"⚠ 空き"&$M5&"日：短工期案件の差し込み検討","空き"&$M5&"日"))))))))
A6: 松田 | B6: =IF($A6="","",IF(COUNTIF('案件台帳'!$J$6:$J$65,$A6)>0,"稼働中","空き中")) | C6: =IF($A6="","",IFERROR(IF(INDEX('案件台帳'!$B$6:$B$65,MATCH($A6,'案件台帳'!$J$6:$J$65,0))="","",INDEX('案件台帳'!$B$6:$B$65,MATCH($A6,'案件台帳'!$J$6:$J$65,0))),"―（現在は空き）")) | D6: =IF($A6="","",IFERROR(IF(INDEX('案件台帳'!$D$6:$D$65,MATCH($A6,'案件台帳'!$J$6:$J$65,0))="","",INDEX('案件台帳'!$D$6:$D$65,MATCH($A6,'案件台帳'!$J$6:$J$65,0))),"")) | E6: =IF($A6="","",IFERROR(IF(INDEX('案件台帳'!$E$6:$E$65,MATCH($A6,'案件台帳'!$J$6:$J$65,0))="","",INDEX('案件台帳'!$E$6:$E$65,MATCH($A6,'案件台帳'!$J$6:$J$65,0))),"")) | F6: =IF($A6="","",IFERROR(IF(INDEX('案件台帳'!$F$6:$F$65,MATCH($A6,'案件台帳'!$J$6:$J$65,0))="","",INDEX('案件台帳'!$F$6:$F$65,MATCH($A6,'案件台帳'!$J$6:$J$65,0))),"")) | G6: =IF(OR($E6="",$F6=""),"",$F6-$E6+1) | H6: =IF($E6="","",'案件台帳'!$B$3-$E6+1) | I6: =IF($F6="","",$F6-'案件台帳'!$B$3) | J6: =IF($A6="","",IF($B6="稼働中",IF($F6="","",$F6+1),IFERROR(IF(INDEX('案件台帳'!$F$6:$F$65,MATCH($A6,'案件台帳'!$L$6:$L$65,0))="","",INDEX('案件台帳'!$F$6:$F$65,MATCH($A6,'案件台帳'!$L$6:$L$65,0))+1),'案件台帳'!$B$3))) | K6: =IF($A6="","",IFERROR(IF(INDEX('案件台帳'!$B$6:$B$65,MATCH($A6,'案件台帳'!$K$6:$K$65,0))="","",INDEX('案件台帳'!$B$6:$B$65,MATCH($A6,'案件台帳'!$K$6:$K$65,0))),"未定")) | L6: =IF($A6="","",IFERROR(IF(INDEX('案件台帳'!$E$6:$E$65,MATCH($A6,'案件台帳'!$K$6:$K$65,0))="","",INDEX('案件台帳'!$E$6:$E$65,MATCH($A6,'案件台帳'!$K$6:$K$65,0))),"")) | M6: =IF(OR($L6="",$J6=""),"",$L6-$J6) | N6: =IF($L6="","",MAX(0,$L6-MAX('案件台帳'!$B$3,$J6))) | O6: =IF($A6="","",SUMIF('案件台帳'!$C$6:$C$65,$A6,'案件台帳'!$H$6:$H$65)) | P6: =IF($A6="","",IF(TRIM(IF(COUNTIFS('案件台帳'!$C$6:$C$65,$A6,'案件台帳'!$E$6:$E$65,"<="&'案件台帳'!$B$3,'案件台帳'!$F$6:$F$65,">="&'案件台帳'!$B$3)>1,"⚠ 重複配置 ","")&IF(COUNTIFS('案件台帳'!$C$6:$C$65,$A6)-COUNTIFS('案件台帳'!$C$6:$C$65,$A6,'案件台帳'!$F$6:$F$65,">0")>0,"⚠ 終了予定日が未入力 ","")&IF($K6="未定","⚠ 次の仕事が未定：営業・見積を前倒し",IF($M6="","",IF($M6<0,"⚠ 前現場と"&ABS($M6)&"日重複",IF($M6=0,"連続稼働（余裕なし）",IF($M6>=7,"⚠ 空き"&$M6&"日：短工期案件の差し込み検討","空き"&$M6&"日"))))))="","OK",TRIM(IF(COUNTIFS('案件台帳'!$C$6:$C$65,$A6,'案件台帳'!$E$6:$E$65,"<="&'案件台帳'!$B$3,'案件台帳'!$F$6:$F$65,">="&'案件台帳'!$B$3)>1,"⚠ 重複配置 ","")&IF(COUNTIFS('案件台帳'!$C$6:$C$65,$A6)-COUNTIFS('案件台帳'!$C$6:$C$65,$A6,'案件台帳'!$F$6:$F$65,">0")>0,"⚠ 終了予定日が未入力 ","")&IF($K6="未定","⚠ 次の仕事が未定：営業・見積を前倒し",IF($M6="","",IF($M6<0,"⚠ 前現場と"&ABS($M6)&"日重複",IF($M6=0,"連続稼働（余裕なし）",IF($M6>=7,"⚠ 空き"&$M6&"日：短工期案件の差し込み検討","空き"&$M6&"日"))))))))
A7: 重田 | B7: =IF($A7="","",IF(COUNTIF('案件台帳'!$J$6:$J$65,$A7)>0,"稼働中","空き中")) | C7: =IF($A7="","",IFERROR(IF(INDEX('案件台帳'!$B$6:$B$65,MATCH($A7,'案件台帳'!$J$6:$J$65,0))="","",INDEX('案件台帳'!$B$6:$B$65,MATCH($A7,'案件台帳'!$J$6:$J$65,0))),"―（現在は空き）")) | D7: =IF($A7="","",IFERROR(IF(INDEX('案件台帳'!$D$6:$D$65,MATCH($A7,'案件台帳'!$J$6:$J$65,0))="","",INDEX('案件台帳'!$D$6:$D$65,MATCH($A7,'案件台帳'!$J$6:$J$65,0))),"")) | E7: =IF($A7="","",IFERROR(IF(INDEX('案件台帳'!$E$6:$E$65,MATCH($A7,'案件台帳'!$J$6:$J$65,0))="","",INDEX('案件台帳'!$E$6:$E$65,MATCH($A7,'案件台帳'!$J$6:$J$65,0))),"")) | F7: =IF($A7="","",IFERROR(IF(INDEX('案件台帳'!$F$6:$F$65,MATCH($A7,'案件台帳'!$J$6:$J$65,0))="","",INDEX('案件台帳'!$F$6:$F$65,MATCH($A7,'案件台帳'!$J$6:$J$65,0))),"")) | G7: =IF(OR($E7="",$F7=""),"",$F7-$E7+1) | H7: =IF($E7="","",'案件台帳'!$B$3-$E7+1) | I7: =IF($F7="","",$F7-'案件台帳'!$B$3) | J7: =IF($A7="","",IF($B7="稼働中",IF($F7="","",$F7+1),IFERROR(IF(INDEX('案件台帳'!$F$6:$F$65,MATCH($A7,'案件台帳'!$L$6:$L$65,0))="","",INDEX('案件台帳'!$F$6:$F$65,MATCH($A7,'案件台帳'!$L$6:$L$65,0))+1),'案件台帳'!$B$3))) | K7: =IF($A7="","",IFERROR(IF(INDEX('案件台帳'!$B$6:$B$65,MATCH($A7,'案件台帳'!$K$6:$K$65,0))="","",INDEX('案件台帳'!$B$6:$B$65,MATCH($A7,'案件台帳'!$K$6:$K$65,0))),"未定")) | L7: =IF($A7="","",IFERROR(IF(INDEX('案件台帳'!$E$6:$E$65,MATCH($A7,'案件台帳'!$K$6:$K$65,0))="","",INDEX('案件台帳'!$E$6:$E$65,MATCH($A7,'案件台帳'!$K$6:$K$65,0))),"")) | M7: =IF(OR($L7="",$J7=""),"",$L7-$J7) | N7: =IF($L7="","",MAX(0,$L7-MAX('案件台帳'!$B$3,$J7))) | O7: =IF($A7="","",SUMIF('案件台帳'!$C$6:$C$65,$A7,'案件台帳'!$H$6:$H$65)) | P7: =IF($A7="","",IF(TRIM(IF(COUNTIFS('案件台帳'!$C$6:$C$65,$A7,'案件台帳'!$E$6:$E$65,"<="&'案件台帳'!$B$3,'案件台帳'!$F$6:$F$65,">="&'案件台帳'!$B$3)>1,"⚠ 重複配置 ","")&IF(COUNTIFS('案件台帳'!$C$6:$C$65,$A7)-COUNTIFS('案件台帳'!$C$6:$C$65,$A7,'案件台帳'!$F$6:$F$65,">0")>0,"⚠ 終了予定日が未入力 ","")&IF($K7="未定","⚠ 次の仕事が未定：営業・見積を前倒し",IF($M7="","",IF($M7<0,"⚠ 前現場と"&ABS($M7)&"日重複",IF($M7=0,"連続稼働（余裕なし）",IF($M7>=7,"⚠ 空き"&$M7&"日：短工期案件の差し込み検討","空き"&$M7&"日"))))))="","OK",TRIM(IF(COUNTIFS('案件台帳'!$C$6:$C$65,$A7,'案件台帳'!$E$6:$E$65,"<="&'案件台帳'!$B$3,'案件台帳'!$F$6:$F$65,">="&'案件台帳'!$B$3)>1,"⚠ 重複配置 ","")&IF(COUNTIFS('案件台帳'!$C$6:$C$65,$A7)-COUNTIFS('案件台帳'!$C$6:$C$65,$A7,'案件台帳'!$F$6:$F$65,">0")>0,"⚠ 終了予定日が未入力 ","")&IF($K7="未定","⚠ 次の仕事が未定：営業・見積を前倒し",IF($M7="","",IF($M7<0,"⚠ 前現場と"&ABS($M7)&"日重複",IF($M7=0,"連続稼働（余裕なし）",IF($M7>=7,"⚠ 空き"&$M7&"日：短工期案件の差し込み検討","空き"&$M7&"日"))))))))
A8: 原田 | B8: =IF($A8="","",IF(COUNTIF('案件台帳'!$J$6:$J$65,$A8)>0,"稼働中","空き中")) | C8: =IF($A8="","",IFERROR(IF(INDEX('案件台帳'!$B$6:$B$65,MATCH($A8,'案件台帳'!$J$6:$J$65,0))="","",INDEX('案件台帳'!$B$6:$B$65,MATCH($A8,'案件台帳'!$J$6:$J$65,0))),"―（現在は空き）")) | D8: =IF($A8="","",IFERROR(IF(INDEX('案件台帳'!$D$6:$D$65,MATCH($A8,'案件台帳'!$J$6:$J$65,0))="","",INDEX('案件台帳'!$D$6:$D$65,MATCH($A8,'案件台帳'!$J$6:$J$65,0))),"")) | E8: =IF($A8="","",IFERROR(IF(INDEX('案件台帳'!$E$6:$E$65,MATCH($A8,'案件台帳'!$J$6:$J$65,0))="","",INDEX('案件台帳'!$E$6:$E$65,MATCH($A8,'案件台帳'!$J$6:$J$65,0))),"")) | F8: =IF($A8="","",IFERROR(IF(INDEX('案件台帳'!$F$6:$F$65,MATCH($A8,'案件台帳'!$J$6:$J$65,0))="","",INDEX('案件台帳'!$F$6:$F$65,MATCH($A8,'案件台帳'!$J$6:$J$65,0))),"")) | G8: =IF(OR($E8="",$F8=""),"",$F8-$E8+1) | H8: =IF($E8="","",'案件台帳'!$B$3-$E8+1) | I8: =IF($F8="","",$F8-'案件台帳'!$B$3) | J8: =IF($A8="","",IF($B8="稼働中",IF($F8="","",$F8+1),IFERROR(IF(INDEX('案件台帳'!$F$6:$F$65,MATCH($A8,'案件台帳'!$L$6:$L$65,0))="","",INDEX('案件台帳'!$F$6:$F$65,MATCH($A8,'案件台帳'!$L$6:$L$65,0))+1),'案件台帳'!$B$3))) | K8: =IF($A8="","",IFERROR(IF(INDEX('案件台帳'!$B$6:$B$65,MATCH($A8,'案件台帳'!$K$6:$K$65,0))="","",INDEX('案件台帳'!$B$6:$B$65,MATCH($A8,'案件台帳'!$K$6:$K$65,0))),"未定")) | L8: =IF($A8="","",IFERROR(IF(INDEX('案件台帳'!$E$6:$E$65,MATCH($A8,'案件台帳'!$K$6:$K$65,0))="","",INDEX('案件台帳'!$E$6:$E$65,MATCH($A8,'案件台帳'!$K$6:$K$65,0))),"")) | M8: =IF(OR($L8="",$J8=""),"",$L8-$J8) | N8: =IF($L8="","",MAX(0,$L8-MAX('案件台帳'!$B$3,$J8))) | O8: =IF($A8="","",SUMIF('案件台帳'!$C$6:$C$65,$A8,'案件台帳'!$H$6:$H$65)) | P8: =IF($A8="","",IF(TRIM(IF(COUNTIFS('案件台帳'!$C$6:$C$65,$A8,'案件台帳'!$E$6:$E$65,"<="&'案件台帳'!$B$3,'案件台帳'!$F$6:$F$65,">="&'案件台帳'!$B$3)>1,"⚠ 重複配置 ","")&IF(COUNTIFS('案件台帳'!$C$6:$C$65,$A8)-COUNTIFS('案件台帳'!$C$6:$C$65,$A8,'案件台帳'!$F$6:$F$65,">0")>0,"⚠ 終了予定日が未入力 ","")&IF($K8="未定","⚠ 次の仕事が未定：営業・見積を前倒し",IF($M8="","",IF($M8<0,"⚠ 前現場と"&ABS($M8)&"日重複",IF($M8=0,"連続稼働（余裕なし）",IF($M8>=7,"⚠ 空き"&$M8&"日：短工期案件の差し込み検討","空き"&$M8&"日"))))))="","OK",TRIM(IF(COUNTIFS('案件台帳'!$C$6:$C$65,$A8,'案件台帳'!$E$6:$E$65,"<="&'案件台帳'!$B$3,'案件台帳'!$F$6:$F$65,">="&'案件台帳'!$B$3)>1,"⚠ 重複配置 ","")&IF(COUNTIFS('案件台帳'!$C$6:$C$65,$A8)-COUNTIFS('案件台帳'!$C$6:$C$65,$A8,'案件台帳'!$F$6:$F$65,">0")>0,"⚠ 終了予定日が未入力 ","")&IF($K8="未定","⚠ 次の仕事が未定：営業・見積を前倒し",IF($M8="","",IF($M8<0,"⚠ 前現場と"&ABS($M8)&"日重複",IF($M8=0,"連続稼働（余裕なし）",IF($M8>=7,"⚠ 空き"&$M8&"日：短工期案件の差し込み検討","空き"&$M8&"日"))))))))
A9: 田中 | B9: =IF($A9="","",IF(COUNTIF('案件台帳'!$J$6:$J$65,$A9)>0,"稼働中","空き中")) | C9: =IF($A9="","",IFERROR(IF(INDEX('案件台帳'!$B$6:$B$65,MATCH($A9,'案件台帳'!$J$6:$J$65,0))="","",INDEX('案件台帳'!$B$6:$B$65,MATCH($A9,'案件台帳'!$J$6:$J$65,0))),"―（現在は空き）")) | D9: =IF($A9="","",IFERROR(IF(INDEX('案件台帳'!$D$6:$D$65,MATCH($A9,'案件台帳'!$J$6:$J$65,0))="","",INDEX('案件台帳'!$D$6:$D$65,MATCH($A9,'案件台帳'!$J$6:$J$65,0))),"")) | E9: =IF($A9="","",IFERROR(IF(INDEX('案件台帳'!$E$6:$E$65,MATCH($A9,'案件台帳'!$J$6:$J$65,0))="","",INDEX('案件台帳'!$E$6:$E$65,MATCH($A9,'案件台帳'!$J$6:$J$65,0))),"")) | F9: =IF($A9="","",IFERROR(IF(INDEX('案件台帳'!$F$6:$F$65,MATCH($A9,'案件台帳'!$J$6:$J$65,0))="","",INDEX('案件台帳'!$F$6:$F$65,MATCH($A9,'案件台帳'!$J$6:$J$65,0))),"")) | G9: =IF(OR($E9="",$F9=""),"",$F9-$E9+1) | H9: =IF($E9="","",'案件台帳'!$B$3-$E9+1) | I9: =IF($F9="","",$F9-'案件台帳'!$B$3) | J9: =IF($A9="","",IF($B9="稼働中",IF($F9="","",$F9+1),IFERROR(IF(INDEX('案件台帳'!$F$6:$F$65,MATCH($A9,'案件台帳'!$L$6:$L$65,0))="","",INDEX('案件台帳'!$F$6:$F$65,MATCH($A9,'案件台帳'!$L$6:$L$65,0))+1),'案件台帳'!$B$3))) | K9: =IF($A9="","",IFERROR(IF(INDEX('案件台帳'!$B$6:$B$65,MATCH($A9,'案件台帳'!$K$6:$K$65,0))="","",INDEX('案件台帳'!$B$6:$B$65,MATCH($A9,'案件台帳'!$K$6:$K$65,0))),"未定")) | L9: =IF($A9="","",IFERROR(IF(INDEX('案件台帳'!$E$6:$E$65,MATCH($A9,'案件台帳'!$K$6:$K$65,0))="","",INDEX('案件台帳'!$E$6:$E$65,MATCH($A9,'案件台帳'!$K$6:$K$65,0))),"")) | M9: =IF(OR($L9="",$J9=""),"",$L9-$J9) | N9: =IF($L9="","",MAX(0,$L9-MAX('案件台帳'!$B$3,$J9))) | O9: =IF($A9="","",SUMIF('案件台帳'!$C$6:$C$65,$A9,'案件台帳'!$H$6:$H$65)) | P9: =IF($A9="","",IF(TRIM(IF(COUNTIFS('案件台帳'!$C$6:$C$65,$A9,'案件台帳'!$E$6:$E$65,"<="&'案件台帳'!$B$3,'案件台帳'!$F$6:$F$65,">="&'案件台帳'!$B$3)>1,"⚠ 重複配置 ","")&IF(COUNTIFS('案件台帳'!$C$6:$C$65,$A9)-COUNTIFS('案件台帳'!$C$6:$C$65,$A9,'案件台帳'!$F$6:$F$65,">0")>0,"⚠ 終了予定日が未入力 ","")&IF($K9="未定","⚠ 次の仕事が未定：営業・見積を前倒し",IF($M9="","",IF($M9<0,"⚠ 前現場と"&ABS($M9)&"日重複",IF($M9=0,"連続稼働（余裕なし）",IF($M9>=7,"⚠ 空き"&$M9&"日：短工期案件の差し込み検討","空き"&$M9&"日"))))))="","OK",TRIM(IF(COUNTIFS('案件台帳'!$C$6:$C$65,$A9,'案件台帳'!$E$6:$E$65,"<="&'案件台帳'!$B$3,'案件台帳'!$F$6:$F$65,">="&'案件台帳'!$B$3)>1,"⚠ 重複配置 ","")&IF(COUNTIFS('案件台帳'!$C$6:$C$65,$A9)-COUNTIFS('案件台帳'!$C$6:$C$65,$A9,'案件台帳'!$F$6:$F$65,">0")>0,"⚠ 終了予定日が未入力 ","")&IF($K9="未定","⚠ 次の仕事が未定：営業・見積を前倒し",IF($M9="","",IF($M9<0,"⚠ 前現場と"&ABS($M9)&"日重複",IF($M9=0,"連続稼働（余裕なし）",IF($M9>=7,"⚠ 空き"&$M9&"日：短工期案件の差し込み検討","空き"&$M9&"日"))))))))
B10: =IF($A10="","",IF(COUNTIF('案件台帳'!$J$6:$J$65,$A10)>0,"稼働中","空き中")) | C10: =IF($A10="","",IFERROR(IF(INDEX('案件台帳'!$B$6:$B$65,MATCH($A10,'案件台帳'!$J$6:$J$65,0))="","",INDEX('案件台帳'!$B$6:$B$65,MATCH($A10,'案件台帳'!$J$6:$J$65,0))),"―（現在は空き）")) | D10: =IF($A10="","",IFERROR(IF(INDEX('案件台帳'!$D$6:$D$65,MATCH($A10,'案件台帳'!$J$6:$J$65,0))="","",INDEX('案件台帳'!$D$6:$D$65,MATCH($A10,'案件台帳'!$J$6:$J$65,0))),"")) | E10: =IF($A10="","",IFERROR(IF(INDEX('案件台帳'!$E$6:$E$65,MATCH($A10,'案件台帳'!$J$6:$J$65,0))="","",INDEX('案件台帳'!$E$6:$E$65,MATCH($A10,'案件台帳'!$J$6:$J$65,0))),"")) | F10: =IF($A10="","",IFERROR(IF(INDEX('案件台帳'!$F$6:$F$65,MATCH($A10,'案件台帳'!$J$6:$J$65,0))="","",INDEX('案件台帳'!$F$6:$F$65,MATCH($A10,'案件台帳'!$J$6:$J$65,0))),"")) | G10: =IF(OR($E10="",$F10=""),"",$F10-$E10+1) | H10: =IF($E10="","",'案件台帳'!$B$3-$E10+1) | I10: =IF($F10="","",$F10-'案件台帳'!$B$3) | J10: =IF($A10="","",IF($B10="稼働中",IF($F10="","",$F10+1),IFERROR(IF(INDEX('案件台帳'!$F$6:$F$65,MATCH($A10,'案件台帳'!$L$6:$L$65,0))="","",INDEX('案件台帳'!$F$6:$F$65,MATCH($A10,'案件台帳'!$L$6:$L$65,0))+1),'案件台帳'!$B$3))) | K10: =IF($A10="","",IFERROR(IF(INDEX('案件台帳'!$B$6:$B$65,MATCH($A10,'案件台帳'!$K$6:$K$65,0))="","",INDEX('案件台帳'!$B$6:$B$65,MATCH($A10,'案件台帳'!$K$6:$K$65,0))),"未定")) | L10: =IF($A10="","",IFERROR(IF(INDEX('案件台帳'!$E$6:$E$65,MATCH($A10,'案件台帳'!$K$6:$K$65,0))="","",INDEX('案件台帳'!$E$6:$E$65,MATCH($A10,'案件台帳'!$K$6:$K$65,0))),"")) | M10: =IF(OR($L10="",$J10=""),"",$L10-$J10) | N10: =IF($L10="","",MAX(0,$L10-MAX('案件台帳'!$B$3,$J10))) | O10: =IF($A10="","",SUMIF('案件台帳'!$C$6:$C$65,$A10,'案件台帳'!$H$6:$H$65)) | P10: =IF($A10="","",IF(TRIM(IF(COUNTIFS('案件台帳'!$C$6:$C$65,$A10,'案件台帳'!$E$6:$E$65,"<="&'案件台帳'!$B$3,'案件台帳'!$F$6:$F$65,">="&'案件台帳'!$B$3)>1,"⚠ 重複配置 ","")&IF(COUNTIFS('案件台帳'!$C$6:$C$65,$A10)-COUNTIFS('案件台帳'!$C$6:$C$65,$A10,'案件台帳'!$F$6:$F$65,">0")>0,"⚠ 終了予定日が未入力 ","")&IF($K10="未定","⚠ 次の仕事が未定：営業・見積を前倒し",IF($M10="","",IF($M10<0,"⚠ 前現場と"&ABS($M10)&"日重複",IF($M10=0,"連続稼働（余裕なし）",IF($M10>=7,"⚠ 空き"&$M10&"日：短工期案件の差し込み検討","空き"&$M10&"日"))))))="","OK",TRIM(IF(COUNTIFS('案件台帳'!$C$6:$C$65,$A10,'案件台帳'!$E$6:$E$65,"<="&'案件台帳'!$B$3,'案件台帳'!$F$6:$F$65,">="&'案件台帳'!$B$3)>1,"⚠ 重複配置 ","")&IF(COUNTIFS('案件台帳'!$C$6:$C$65,$A10)-COUNTIFS('案件台帳'!$C$6:$C$65,$A10,'案件台帳'!$F$6:$F$65,">0")>0,"⚠ 終了予定日が未入力 ","")&IF($K10="未定","⚠ 次の仕事が未定：営業・見積を前倒し",IF($M10="","",IF($M10<0,"⚠ 前現場と"&ABS($M10)&"日重複",IF($M10=0,"連続稼働（余裕なし）",IF($M10>=7,"⚠ 空き"&$M10&"日：短工期案件の差し込み検討","空き"&$M10&"日"))))))))
B11: =IF($A11="","",IF(COUNTIF('案件台帳'!$J$6:$J$65,$A11)>0,"稼働中","空き中")) | C11: =IF($A11="","",IFERROR(IF(INDEX('案件台帳'!$B$6:$B$65,MATCH($A11,'案件台帳'!$J$6:$J$65,0))="","",INDEX('案件台帳'!$B$6:$B$65,MATCH($A11,'案件台帳'!$J$6:$J$65,0))),"―（現在は空き）")) | D11: =IF($A11="","",IFERROR(IF(INDEX('案件台帳'!$D$6:$D$65,MATCH($A11,'案件台帳'!$J$6:$J$65,0))="","",INDEX('案件台帳'!$D$6:$D$65,MATCH($A11,'案件台帳'!$J$6:$J$65,0))),"")) | E11: =IF($A11="","",IFERROR(IF(INDEX('案件台帳'!$E$6:$E$65,MATCH($A11,'案件台帳'!$J$6:$J$65,0))="","",INDEX('案件台帳'!$E$6:$E$65,MATCH($A11,'案件台帳'!$J$6:$J$65,0))),"")) | F11: =IF($A11="","",IFERROR(IF(INDEX('案件台帳'!$F$6:$F$65,MATCH($A11,'案件台帳'!$J$6:$J$65,0))="","",INDEX('案件台帳'!$F$6:$F$65,MATCH($A11,'案件台帳'!$J$6:$J$65,0))),"")) | G11: =IF(OR($E11="",$F11=""),"",$F11-$E11+1) | H11: =IF($E11="","",'案件台帳'!$B$3-$E11+1) | I11: =IF($F11="","",$F11-'案件台帳'!$B$3) | J11: =IF($A11="","",IF($B11="稼働中",IF($F11="","",$F11+1),IFERROR(IF(INDEX('案件台帳'!$F$6:$F$65,MATCH($A11,'案件台帳'!$L$6:$L$65,0))="","",INDEX('案件台帳'!$F$6:$F$65,MATCH($A11,'案件台帳'!$L$6:$L$65,0))+1),'案件台帳'!$B$3))) | K11: =IF($A11="","",IFERROR(IF(INDEX('案件台帳'!$B$6:$B$65,MATCH($A11,'案件台帳'!$K$6:$K$65,0))="","",INDEX('案件台帳'!$B$6:$B$65,MATCH($A11,'案件台帳'!$K$6:$K$65,0))),"未定")) | L11: =IF($A11="","",IFERROR(IF(INDEX('案件台帳'!$E$6:$E$65,MATCH($A11,'案件台帳'!$K$6:$K$65,0))="","",INDEX('案件台帳'!$E$6:$E$65,MATCH($A11,'案件台帳'!$K$6:$K$65,0))),"")) | M11: =IF(OR($L11="",$J11=""),"",$L11-$J11) | N11: =IF($L11="","",MAX(0,$L11-MAX('案件台帳'!$B$3,$J11))) | O11: =IF($A11="","",SUMIF('案件台帳'!$C$6:$C$65,$A11,'案件台帳'!$H$6:$H$65)) | P11: =IF($A11="","",IF(TRIM(IF(COUNTIFS('案件台帳'!$C$6:$C$65,$A11,'案件台帳'!$E$6:$E$65,"<="&'案件台帳'!$B$3,'案件台帳'!$F$6:$F$65,">="&'案件台帳'!$B$3)>1,"⚠ 重複配置 ","")&IF(COUNTIFS('案件台帳'!$C$6:$C$65,$A11)-COUNTIFS('案件台帳'!$C$6:$C$65,$A11,'案件台帳'!$F$6:$F$65,">0")>0,"⚠ 終了予定日が未入力 ","")&IF($K11="未定","⚠ 次の仕事が未定：営業・見積を前倒し",IF($M11="","",IF($M11<0,"⚠ 前現場と"&ABS($M11)&"日重複",IF($M11=0,"連続稼働（余裕なし）",IF($M11>=7,"⚠ 空き"&$M11&"日：短工期案件の差し込み検討","空き"&$M11&"日"))))))="","OK",TRIM(IF(COUNTIFS('案件台帳'!$C$6:$C$65,$A11,'案件台帳'!$E$6:$E$65,"<="&'案件台帳'!$B$3,'案件台帳'!$F$6:$F$65,">="&'案件台帳'!$B$3)>1,"⚠ 重複配置 ","")&IF(COUNTIFS('案件台帳'!$C$6:$C$65,$A11)-COUNTIFS('案件台帳'!$C$6:$C$65,$A11,'案件台帳'!$F$6:$F$65,">0")>0,"⚠ 終了予定日が未入力 ","")&IF($K11="未定","⚠ 次の仕事が未定：営業・見積を前倒し",IF($M11="","",IF($M11<0,"⚠ 前現場と"&ABS($M11)&"日重複",IF($M11=0,"連続稼働（余裕なし）",IF($M11>=7,"⚠ 空き"&$M11&"日：短工期案件の差し込み検討","空き"&$M11&"日"))))))))
B12: =IF($A12="","",IF(COUNTIF('案件台帳'!$J$6:$J$65,$A12)>0,"稼働中","空き中")) | C12: =IF($A12="","",IFERROR(IF(INDEX('案件台帳'!$B$6:$B$65,MATCH($A12,'案件台帳'!$J$6:$J$65,0))="","",INDEX('案件台帳'!$B$6:$B$65,MATCH($A12,'案件台帳'!$J$6:$J$65,0))),"―（現在は空き）")) | D12: =IF($A12="","",IFERROR(IF(INDEX('案件台帳'!$D$6:$D$65,MATCH($A12,'案件台帳'!$J$6:$J$65,0))="","",INDEX('案件台帳'!$D$6:$D$65,MATCH($A12,'案件台帳'!$J$6:$J$65,0))),"")) | E12: =IF($A12="","",IFERROR(IF(INDEX('案件台帳'!$E$6:$E$65,MATCH($A12,'案件台帳'!$J$6:$J$65,0))="","",INDEX('案件台帳'!$E$6:$E$65,MATCH($A12,'案件台帳'!$J$6:$J$65,0))),"")) | F12: =IF($A12="","",IFERROR(IF(INDEX('案件台帳'!$F$6:$F$65,MATCH($A12,'案件台帳'!$J$6:$J$65,0))="","",INDEX('案件台帳'!$F$6:$F$65,MATCH($A12,'案件台帳'!$J$6:$J$65,0))),"")) | G12: =IF(OR($E12="",$F12=""),"",$F12-$E12+1) | H12: =IF($E12="","",'案件台帳'!$B$3-$E12+1) | I12: =IF($F12="","",$F12-'案件台帳'!$B$3) | J12: =IF($A12="","",IF($B12="稼働中",IF($F12="","",$F12+1),IFERROR(IF(INDEX('案件台帳'!$F$6:$F$65,MATCH($A12,'案件台帳'!$L$6:$L$65,0))="","",INDEX('案件台帳'!$F$6:$F$65,MATCH($A12,'案件台帳'!$L$6:$L$65,0))+1),'案件台帳'!$B$3))) | K12: =IF($A12="","",IFERROR(IF(INDEX('案件台帳'!$B$6:$B$65,MATCH($A12,'案件台帳'!$K$6:$K$65,0))="","",INDEX('案件台帳'!$B$6:$B$65,MATCH($A12,'案件台帳'!$K$6:$K$65,0))),"未定")) | L12: =IF($A12="","",IFERROR(IF(INDEX('案件台帳'!$E$6:$E$65,MATCH($A12,'案件台帳'!$K$6:$K$65,0))="","",INDEX('案件台帳'!$E$6:$E$65,MATCH($A12,'案件台帳'!$K$6:$K$65,0))),"")) | M12: =IF(OR($L12="",$J12=""),"",$L12-$J12) | N12: =IF($L12="","",MAX(0,$L12-MAX('案件台帳'!$B$3,$J12))) | O12: =IF($A12="","",SUMIF('案件台帳'!$C$6:$C$65,$A12,'案件台帳'!$H$6:$H$65)) | P12: =IF($A12="","",IF(TRIM(IF(COUNTIFS('案件台帳'!$C$6:$C$65,$A12,'案件台帳'!$E$6:$E$65,"<="&'案件台帳'!$B$3,'案件台帳'!$F$6:$F$65,">="&'案件台帳'!$B$3)>1,"⚠ 重複配置 ","")&IF(COUNTIFS('案件台帳'!$C$6:$C$65,$A12)-COUNTIFS('案件台帳'!$C$6:$C$65,$A12,'案件台帳'!$F$6:$F$65,">0")>0,"⚠ 終了予定日が未入力 ","")&IF($K12="未定","⚠ 次の仕事が未定：営業・見積を前倒し",IF($M12="","",IF($M12<0,"⚠ 前現場と"&ABS($M12)&"日重複",IF($M12=0,"連続稼働（余裕なし）",IF($M12>=7,"⚠ 空き"&$M12&"日：短工期案件の差し込み検討","空き"&$M12&"日"))))))="","OK",TRIM(IF(COUNTIFS('案件台帳'!$C$6:$C$65,$A12,'案件台帳'!$E$6:$E$65,"<="&'案件台帳'!$B$3,'案件台帳'!$F$6:$F$65,">="&'案件台帳'!$B$3)>1,"⚠ 重複配置 ","")&IF(COUNTIFS('案件台帳'!$C$6:$C$65,$A12)-COUNTIFS('案件台帳'!$C$6:$C$65,$A12,'案件台帳'!$F$6:$F$65,">0")>0,"⚠ 終了予定日が未入力 ","")&IF($K12="未定","⚠ 次の仕事が未定：営業・見積を前倒し",IF($M12="","",IF($M12<0,"⚠ 前現場と"&ABS($M12)&"日重複",IF($M12=0,"連続稼働（余裕なし）",IF($M12>=7,"⚠ 空き"&$M12&"日：短工期案件の差し込み検討","空き"&$M12&"日"))))))))
B13: =IF($A13="","",IF(COUNTIF('案件台帳'!$J$6:$J$65,$A13)>0,"稼働中","空き中")) | C13: =IF($A13="","",IFERROR(IF(INDEX('案件台帳'!$B$6:$B$65,MATCH($A13,'案件台帳'!$J$6:$J$65,0))="","",INDEX('案件台帳'!$B$6:$B$65,MATCH($A13,'案件台帳'!$J$6:$J$65,0))),"―（現在は空き）")) | D13: =IF($A13="","",IFERROR(IF(INDEX('案件台帳'!$D$6:$D$65,MATCH($A13,'案件台帳'!$J$6:$J$65,0))="","",INDEX('案件台帳'!$D$6:$D$65,MATCH($A13,'案件台帳'!$J$6:$J$65,0))),"")) | E13: =IF($A13="","",IFERROR(IF(INDEX('案件台帳'!$E$6:$E$65,MATCH($A13,'案件台帳'!$J$6:$J$65,0))="","",INDEX('案件台帳'!$E$6:$E$65,MATCH($A13,'案件台帳'!$J$6:$J$65,0))),"")) | F13: =IF($A13="","",IFERROR(IF(INDEX('案件台帳'!$F$6:$F$65,MATCH($A13,'案件台帳'!$J$6:$J$65,0))="","",INDEX('案件台帳'!$F$6:$F$65,MATCH($A13,'案件台帳'!$J$6:$J$65,0))),"")) | G13: =IF(OR($E13="",$F13=""),"",$F13-$E13+1) | H13: =IF($E13="","",'案件台帳'!$B$3-$E13+1) | I13: =IF($F13="","",$F13-'案件台帳'!$B$3) | J13: =IF($A13="","",IF($B13="稼働中",IF($F13="","",$F13+1),IFERROR(IF(INDEX('案件台帳'!$F$6:$F$65,MATCH($A13,'案件台帳'!$L$6:$L$65,0))="","",INDEX('案件台帳'!$F$6:$F$65,MATCH($A13,'案件台帳'!$L$6:$L$65,0))+1),'案件台帳'!$B$3))) | K13: =IF($A13="","",IFERROR(IF(INDEX('案件台帳'!$B$6:$B$65,MATCH($A13,'案件台帳'!$K$6:$K$65,0))="","",INDEX('案件台帳'!$B$6:$B$65,MATCH($A13,'案件台帳'!$K$6:$K$65,0))),"未定")) | L13: =IF($A13="","",IFERROR(IF(INDEX('案件台帳'!$E$6:$E$65,MATCH($A13,'案件台帳'!$K$6:$K$65,0))="","",INDEX('案件台帳'!$E$6:$E$65,MATCH($A13,'案件台帳'!$K$6:$K$65,0))),"")) | M13: =IF(OR($L13="",$J13=""),"",$L13-$J13) | N13: =IF($L13="","",MAX(0,$L13-MAX('案件台帳'!$B$3,$J13))) | O13: =IF($A13="","",SUMIF('案件台帳'!$C$6:$C$65,$A13,'案件台帳'!$H$6:$H$65)) | P13: =IF($A13="","",IF(TRIM(IF(COUNTIFS('案件台帳'!$C$6:$C$65,$A13,'案件台帳'!$E$6:$E$65,"<="&'案件台帳'!$B$3,'案件台帳'!$F$6:$F$65,">="&'案件台帳'!$B$3)>1,"⚠ 重複配置 ","")&IF(COUNTIFS('案件台帳'!$C$6:$C$65,$A13)-COUNTIFS('案件台帳'!$C$6:$C$65,$A13,'案件台帳'!$F$6:$F$65,">0")>0,"⚠ 終了予定日が未入力 ","")&IF($K13="未定","⚠ 次の仕事が未定：営業・見積を前倒し",IF($M13="","",IF($M13<0,"⚠ 前現場と"&ABS($M13)&"日重複",IF($M13=0,"連続稼働（余裕なし）",IF($M13>=7,"⚠ 空き"&$M13&"日：短工期案件の差し込み検討","空き"&$M13&"日"))))))="","OK",TRIM(IF(COUNTIFS('案件台帳'!$C$6:$C$65,$A13,'案件台帳'!$E$6:$E$65,"<="&'案件台帳'!$B$3,'案件台帳'!$F$6:$F$65,">="&'案件台帳'!$B$3)>1,"⚠ 重複配置 ","")&IF(COUNTIFS('案件台帳'!$C$6:$C$65,$A13)-COUNTIFS('案件台帳'!$C$6:$C$65,$A13,'案件台帳'!$F$6:$F$65,">0")>0,"⚠ 終了予定日が未入力 ","")&IF($K13="未定","⚠ 次の仕事が未定：営業・見積を前倒し",IF($M13="","",IF($M13<0,"⚠ 前現場と"&ABS($M13)&"日重複",IF($M13=0,"連続稼働（余裕なし）",IF($M13>=7,"⚠ 空き"&$M13&"日：短工期案件の差し込み検討","空き"&$M13&"日"))))))))
B14: =IF($A14="","",IF(COUNTIF('案件台帳'!$J$6:$J$65,$A14)>0,"稼働中","空き中")) | C14: =IF($A14="","",IFERROR(IF(INDEX('案件台帳'!$B$6:$B$65,MATCH($A14,'案件台帳'!$J$6:$J$65,0))="","",INDEX('案件台帳'!$B$6:$B$65,MATCH($A14,'案件台帳'!$J$6:$J$65,0))),"―（現在は空き）")) | D14: =IF($A14="","",IFERROR(IF(INDEX('案件台帳'!$D$6:$D$65,MATCH($A14,'案件台帳'!$J$6:$J$65,0))="","",INDEX('案件台帳'!$D$6:$D$65,MATCH($A14,'案件台帳'!$J$6:$J$65,0))),"")) | E14: =IF($A14="","",IFERROR(IF(INDEX('案件台帳'!$E$6:$E$65,MATCH($A14,'案件台帳'!$J$6:$J$65,0))="","",INDEX('案件台帳'!$E$6:$E$65,MATCH($A14,'案件台帳'!$J$6:$J$65,0))),"")) | F14: =IF($A14="","",IFERROR(IF(INDEX('案件台帳'!$F$6:$F$65,MATCH($A14,'案件台帳'!$J$6:$J$65,0))="","",INDEX('案件台帳'!$F$6:$F$65,MATCH($A14,'案件台帳'!$J$6:$J$65,0))),"")) | G14: =IF(OR($E14="",$F14=""),"",$F14-$E14+1) | H14: =IF($E14="","",'案件台帳'!$B$3-$E14+1) | I14: =IF($F14="","",$F14-'案件台帳'!$B$3) | J14: =IF($A14="","",IF($B14="稼働中",IF($F14="","",$F14+1),IFERROR(IF(INDEX('案件台帳'!$F$6:$F$65,MATCH($A14,'案件台帳'!$L$6:$L$65,0))="","",INDEX('案件台帳'!$F$6:$F$65,MATCH($A14,'案件台帳'!$L$6:$L$65,0))+1),'案件台帳'!$B$3))) | K14: =IF($A14="","",IFERROR(IF(INDEX('案件台帳'!$B$6:$B$65,MATCH($A14,'案件台帳'!$K$6:$K$65,0))="","",INDEX('案件台帳'!$B$6:$B$65,MATCH($A14,'案件台帳'!$K$6:$K$65,0))),"未定")) | L14: =IF($A14="","",IFERROR(IF(INDEX('案件台帳'!$E$6:$E$65,MATCH($A14,'案件台帳'!$K$6:$K$65,0))="","",INDEX('案件台帳'!$E$6:$E$65,MATCH($A14,'案件台帳'!$K$6:$K$65,0))),"")) | M14: =IF(OR($L14="",$J14=""),"",$L14-$J14) | N14: =IF($L14="","",MAX(0,$L14-MAX('案件台帳'!$B$3,$J14))) | O14: =IF($A14="","",SUMIF('案件台帳'!$C$6:$C$65,$A14,'案件台帳'!$H$6:$H$65)) | P14: =IF($A14="","",IF(TRIM(IF(COUNTIFS('案件台帳'!$C$6:$C$65,$A14,'案件台帳'!$E$6:$E$65,"<="&'案件台帳'!$B$3,'案件台帳'!$F$6:$F$65,">="&'案件台帳'!$B$3)>1,"⚠ 重複配置 ","")&IF(COUNTIFS('案件台帳'!$C$6:$C$65,$A14)-COUNTIFS('案件台帳'!$C$6:$C$65,$A14,'案件台帳'!$F$6:$F$65,">0")>0,"⚠ 終了予定日が未入力 ","")&IF($K14="未定","⚠ 次の仕事が未定：営業・見積を前倒し",IF($M14="","",IF($M14<0,"⚠ 前現場と"&ABS($M14)&"日重複",IF($M14=0,"連続稼働（余裕なし）",IF($M14>=7,"⚠ 空き"&$M14&"日：短工期案件の差し込み検討","空き"&$M14&"日"))))))="","OK",TRIM(IF(COUNTIFS('案件台帳'!$C$6:$C$65,$A14,'案件台帳'!$E$6:$E$65,"<="&'案件台帳'!$B$3,'案件台帳'!$F$6:$F$65,">="&'案件台帳'!$B$3)>1,"⚠ 重複配置 ","")&IF(COUNTIFS('案件台帳'!$C$6:$C$65,$A14)-COUNTIFS('案件台帳'!$C$6:$C$65,$A14,'案件台帳'!$F$6:$F$65,">0")>0,"⚠ 終了予定日が未入力 ","")&IF($K14="未定","⚠ 次の仕事が未定：営業・見積を前倒し",IF($M14="","",IF($M14<0,"⚠ 前現場と"&ABS($M14)&"日重複",IF($M14=0,"連続稼働（余裕なし）",IF($M14>=7,"⚠ 空き"&$M14&"日：短工期案件の差し込み検討","空き"&$M14&"日"))))))))
A16: 見方： | B16: 「工期日数」＝終了予定日−開始日＋1（今の現場に入っている総日数）／「経過日数」＝基準日−開始日＋1／「次の仕事までの空き日数」＝次回開始日−空き開始日（0＝連続、マイナス＝重複）
B17: 職人を増やすときはA列に名前を追加してください（14行目まで数式が入っています）。名前は案件台帳の職人名と完全に一致させること。

Sheet 配置検討
A1: ③ 次の仕事は誰を配置するか（空き状況からの自動判定）
A2: 黄色の3つ（案件名・希望開始日・必要工期）を入れると、職人ごとの可否と推奨順位が出ます。
A4: 候補案件名 | B4: （例）新規引き合いA様邸
A5: 希望開始日 | B5: 46266
A6: 必要工期（日） | B6: 14
A7: 希望終了日（自動） | B7: =IF(OR($B$5="",$B$6=""),"",$B$5+$B$6-1) | C7: ← 希望開始日 ＋ 必要工期 − 1
A9: 職人 | B9: 判定 | C9: 推奨 順位 | D9: 希望開始日 の状況 | E9: 重複件数 (確定) | F9: 要確認件数 (日付未入力) | G9: 重複・要確認の物件 | H9: 手が空く日 | I9: 待ち日数 | J9: 次の仕事までの 空き日数 | K9: 推奨スコア
A10: =IF(職人ダッシュボード!$A$5="","",職人ダッシュボード!$A$5) | B10: =IF(OR($A10="",$E10=""),"",IF($E10>0,IF(AND($D10="稼働中",ISNUMBER($I10),$I10<=7),"△ "&$I10&"日ずらせば可","× 期間が重複"),IF($F10>0,"▲ 要確認（終了日未入力の案件あり）","◎ そのまま配置可"))) | C10: =IF(OR($A10="",$K10=""),"",RANK($K10,$K$10:$K$19)) | D10: =IF($A10="","",IF(COUNTIFS('案件台帳'!$C$6:$C$65,$A10,'案件台帳'!$E$6:$E$65,"<="&$B$5,'案件台帳'!$F$6:$F$65,">="&$B$5)>0,"稼働中","空き")) | E10: =IF(OR($A10="",$B$7=""),"",COUNTIFS('案件台帳'!$C$6:$C$65,$A10,'案件台帳'!$E$6:$E$65,"<="&$B$7,'案件台帳'!$F$6:$F$65,">="&$B$5)) | F10: =IF(OR($A10="",$B$7=""),"",COUNTIFS('案件台帳'!$C$6:$C$65,$A10,'案件台帳'!$E$6:$E$65,"<="&$B$7)-COUNTIFS('案件台帳'!$C$6:$C$65,$A10,'案件台帳'!$E$6:$E$65,"<="&$B$7,'案件台帳'!$F$6:$F$65,">0")+COUNTIFS('案件台帳'!$C$6:$C$65,$A10,'案件台帳'!$E$6:$E$65,"",'案件台帳'!$F$6:$F$65,">="&$B$5)) | G10: =IF(OR($A10="",$E10=""),"",IF($E10+$F10=0,"—",IFERROR(INDEX('案件台帳'!$B$6:$B$65,SUMPRODUCT(MAX(('案件台帳'!$C$6:$C$65=$A10)*('案件台帳'!$E$6:$E$65<=$B$7)*(('案件台帳'!$F$6:$F$65>=$B$5)+('案件台帳'!$F$6:$F$65=""))*ROW('案件台帳'!$C$6:$C$65)))-5),""))) | H10: =IF($A10="","",IF($D10="空き",$B$5,IF(SUMIFS('案件台帳'!$F$6:$F$65,'案件台帳'!$C$6:$C$65,$A10,'案件台帳'!$E$6:$E$65,"<="&$B$5,'案件台帳'!$F$6:$F$65,">="&$B$5)=0,"",SUMIFS('案件台帳'!$F$6:$F$65,'案件台帳'!$C$6:$C$65,$A10,'案件台帳'!$E$6:$E$65,"<="&$B$5,'案件台帳'!$F$6:$F$65,">="&$B$5)+1))) | I10: =IF(OR($A10="",$H10=""),"",MAX(0,$H10-$B$5)) | J10: =IF($A10="","",IFERROR(INDEX(職人ダッシュボード!$M$5:$M$14,MATCH($A10,職人ダッシュボード!$A$5:$A$14,0)),"")) | K10: =IF(OR($A10="",$E10=""),"",IF($E10>0,IF(AND($D10="稼働中",ISNUMBER($I10),$I10<=7),MAX(0,60-$I10*2),0),IF($F10>0,70,100))+IF(ISNUMBER($J10),MIN(MAX($J10,0),30),0))
A11: =IF(職人ダッシュボード!$A$6="","",職人ダッシュボード!$A$6) | B11: =IF(OR($A11="",$E11=""),"",IF($E11>0,IF(AND($D11="稼働中",ISNUMBER($I11),$I11<=7),"△ "&$I11&"日ずらせば可","× 期間が重複"),IF($F11>0,"▲ 要確認（終了日未入力の案件あり）","◎ そのまま配置可"))) | C11: =IF(OR($A11="",$K11=""),"",RANK($K11,$K$10:$K$19)) | D11: =IF($A11="","",IF(COUNTIFS('案件台帳'!$C$6:$C$65,$A11,'案件台帳'!$E$6:$E$65,"<="&$B$5,'案件台帳'!$F$6:$F$65,">="&$B$5)>0,"稼働中","空き")) | E11: =IF(OR($A11="",$B$7=""),"",COUNTIFS('案件台帳'!$C$6:$C$65,$A11,'案件台帳'!$E$6:$E$65,"<="&$B$7,'案件台帳'!$F$6:$F$65,">="&$B$5)) | F11: =IF(OR($A11="",$B$7=""),"",COUNTIFS('案件台帳'!$C$6:$C$65,$A11,'案件台帳'!$E$6:$E$65,"<="&$B$7)-COUNTIFS('案件台帳'!$C$6:$C$65,$A11,'案件台帳'!$E$6:$E$65,"<="&$B$7,'案件台帳'!$F$6:$F$65,">0")+COUNTIFS('案件台帳'!$C$6:$C$65,$A11,'案件台帳'!$E$6:$E$65,"",'案件台帳'!$F$6:$F$65,">="&$B$5)) | G11: =IF(OR($A11="",$E11=""),"",IF($E11+$F11=0,"—",IFERROR(INDEX('案件台帳'!$B$6:$B$65,SUMPRODUCT(MAX(('案件台帳'!$C$6:$C$65=$A11)*('案件台帳'!$E$6:$E$65<=$B$7)*(('案件台帳'!$F$6:$F$65>=$B$5)+('案件台帳'!$F$6:$F$65=""))*ROW('案件台帳'!$C$6:$C$65)))-5),""))) | H11: =IF($A11="","",IF($D11="空き",$B$5,IF(SUMIFS('案件台帳'!$F$6:$F$65,'案件台帳'!$C$6:$C$65,$A11,'案件台帳'!$E$6:$E$65,"<="&$B$5,'案件台帳'!$F$6:$F$65,">="&$B$5)=0,"",SUMIFS('案件台帳'!$F$6:$F$65,'案件台帳'!$C$6:$C$65,$A11,'案件台帳'!$E$6:$E$65,"<="&$B$5,'案件台帳'!$F$6:$F$65,">="&$B$5)+1))) | I11: =IF(OR($A11="",$H11=""),"",MAX(0,$H11-$B$5)) | J11: =IF($A11="","",IFERROR(INDEX(職人ダッシュボード!$M$5:$M$14,MATCH($A11,職人ダッシュボード!$A$5:$A$14,0)),"")) | K11: =IF(OR($A11="",$E11=""),"",IF($E11>0,IF(AND($D11="稼働中",ISNUMBER($I11),$I11<=7),MAX(0,60-$I11*2),0),IF($F11>0,70,100))+IF(ISNUMBER($J11),MIN(MAX($J11,0),30),0))
A12: =IF(職人ダッシュボード!$A$7="","",職人ダッシュボード!$A$7) | B12: =IF(OR($A12="",$E12=""),"",IF($E12>0,IF(AND($D12="稼働中",ISNUMBER($I12),$I12<=7),"△ "&$I12&"日ずらせば可","× 期間が重複"),IF($F12>0,"▲ 要確認（終了日未入力の案件あり）","◎ そのまま配置可"))) | C12: =IF(OR($A12="",$K12=""),"",RANK($K12,$K$10:$K$19)) | D12: =IF($A12="","",IF(COUNTIFS('案件台帳'!$C$6:$C$65,$A12,'案件台帳'!$E$6:$E$65,"<="&$B$5,'案件台帳'!$F$6:$F$65,">="&$B$5)>0,"稼働中","空き")) | E12: =IF(OR($A12="",$B$7=""),"",COUNTIFS('案件台帳'!$C$6:$C$65,$A12,'案件台帳'!$E$6:$E$65,"<="&$B$7,'案件台帳'!$F$6:$F$65,">="&$B$5)) | F12: =IF(OR($A12="",$B$7=""),"",COUNTIFS('案件台帳'!$C$6:$C$65,$A12,'案件台帳'!$E$6:$E$65,"<="&$B$7)-COUNTIFS('案件台帳'!$C$6:$C$65,$A12,'案件台帳'!$E$6:$E$65,"<="&$B$7,'案件台帳'!$F$6:$F$65,">0")+COUNTIFS('案件台帳'!$C$6:$C$65,$A12,'案件台帳'!$E$6:$E$65,"",'案件台帳'!$F$6:$F$65,">="&$B$5)) | G12: =IF(OR($A12="",$E12=""),"",IF($E12+$F12=0,"—",IFERROR(INDEX('案件台帳'!$B$6:$B$65,SUMPRODUCT(MAX(('案件台帳'!$C$6:$C$65=$A12)*('案件台帳'!$E$6:$E$65<=$B$7)*(('案件台帳'!$F$6:$F$65>=$B$5)+('案件台帳'!$F$6:$F$65=""))*ROW('案件台帳'!$C$6:$C$65)))-5),""))) | H12: =IF($A12="","",IF($D12="空き",$B$5,IF(SUMIFS('案件台帳'!$F$6:$F$65,'案件台帳'!$C$6:$C$65,$A12,'案件台帳'!$E$6:$E$65,"<="&$B$5,'案件台帳'!$F$6:$F$65,">="&$B$5)=0,"",SUMIFS('案件台帳'!$F$6:$F$65,'案件台帳'!$C$6:$C$65,$A12,'案件台帳'!$E$6:$E$65,"<="&$B$5,'案件台帳'!$F$6:$F$65,">="&$B$5)+1))) | I12: =IF(OR($A12="",$H12=""),"",MAX(0,$H12-$B$5)) | J12: =IF($A12="","",IFERROR(INDEX(職人ダッシュボード!$M$5:$M$14,MATCH($A12,職人ダッシュボード!$A$5:$A$14,0)),"")) | K12: =IF(OR($A12="",$E12=""),"",IF($E12>0,IF(AND($D12="稼働中",ISNUMBER($I12),$I12<=7),MAX(0,60-$I12*2),0),IF($F12>0,70,100))+IF(ISNUMBER($J12),MIN(MAX($J12,0),30),0))
A13: =IF(職人ダッシュボード!$A$8="","",職人ダッシュボード!$A$8) | B13: =IF(OR($A13="",$E13=""),"",IF($E13>0,IF(AND($D13="稼働中",ISNUMBER($I13),$I13<=7),"△ "&$I13&"日ずらせば可","× 期間が重複"),IF($F13>0,"▲ 要確認（終了日未入力の案件あり）","◎ そのまま配置可"))) | C13: =IF(OR($A13="",$K13=""),"",RANK($K13,$K$10:$K$19)) | D13: =IF($A13="","",IF(COUNTIFS('案件台帳'!$C$6:$C$65,$A13,'案件台帳'!$E$6:$E$65,"<="&$B$5,'案件台帳'!$F$6:$F$65,">="&$B$5)>0,"稼働中","空き")) | E13: =IF(OR($A13="",$B$7=""),"",COUNTIFS('案件台帳'!$C$6:$C$65,$A13,'案件台帳'!$E$6:$E$65,"<="&$B$7,'案件台帳'!$F$6:$F$65,">="&$B$5)) | F13: =IF(OR($A13="",$B$7=""),"",COUNTIFS('案件台帳'!$C$6:$C$65,$A13,'案件台帳'!$E$6:$E$65,"<="&$B$7)-COUNTIFS('案件台帳'!$C$6:$C$65,$A13,'案件台帳'!$E$6:$E$65,"<="&$B$7,'案件台帳'!$F$6:$F$65,">0")+COUNTIFS('案件台帳'!$C$6:$C$65,$A13,'案件台帳'!$E$6:$E$65,"",'案件台帳'!$F$6:$F$65,">="&$B$5)) | G13: =IF(OR($A13="",$E13=""),"",IF($E13+$F13=0,"—",IFERROR(INDEX('案件台帳'!$B$6:$B$65,SUMPRODUCT(MAX(('案件台帳'!$C$6:$C$65=$A13)*('案件台帳'!$E$6:$E$65<=$B$7)*(('案件台帳'!$F$6:$F$65>=$B$5)+('案件台帳'!$F$6:$F$65=""))*ROW('案件台帳'!$C$6:$C$65)))-5),""))) | H13: =IF($A13="","",IF($D13="空き",$B$5,IF(SUMIFS('案件台帳'!$F$6:$F$65,'案件台帳'!$C$6:$C$65,$A13,'案件台帳'!$E$6:$E$65,"<="&$B$5,'案件台帳'!$F$6:$F$65,">="&$B$5)=0,"",SUMIFS('案件台帳'!$F$6:$F$65,'案件台帳'!$C$6:$C$65,$A13,'案件台帳'!$E$6:$E$65,"<="&$B$5,'案件台帳'!$F$6:$F$65,">="&$B$5)+1))) | I13: =IF(OR($A13="",$H13=""),"",MAX(0,$H13-$B$5)) | J13: =IF($A13="","",IFERROR(INDEX(職人ダッシュボード!$M$5:$M$14,MATCH($A13,職人ダッシュボード!$A$5:$A$14,0)),"")) | K13: =IF(OR($A13="",$E13=""),"",IF($E13>0,IF(AND($D13="稼働中",ISNUMBER($I13),$I13<=7),MAX(0,60-$I13*2),0),IF($F13>0,70,100))+IF(ISNUMBER($J13),MIN(MAX($J13,0),30),0))
A14: =IF(職人ダッシュボード!$A$9="","",職人ダッシュボード!$A$9) | B14: =IF(OR($A14="",$E14=""),"",IF($E14>0,IF(AND($D14="稼働中",ISNUMBER($I14),$I14<=7),"△ "&$I14&"日ずらせば可","× 期間が重複"),IF($F14>0,"▲ 要確認（終了日未入力の案件あり）","◎ そのまま配置可"))) | C14: =IF(OR($A14="",$K14=""),"",RANK($K14,$K$10:$K$19)) | D14: =IF($A14="","",IF(COUNTIFS('案件台帳'!$C$6:$C$65,$A14,'案件台帳'!$E$6:$E$65,"<="&$B$5,'案件台帳'!$F$6:$F$65,">="&$B$5)>0,"稼働中","空き")) | E14: =IF(OR($A14="",$B$7=""),"",COUNTIFS('案件台帳'!$C$6:$C$65,$A14,'案件台帳'!$E$6:$E$65,"<="&$B$7,'案件台帳'!$F$6:$F$65,">="&$B$5)) | F14: =IF(OR($A14="",$B$7=""),"",COUNTIFS('案件台帳'!$C$6:$C$65,$A14,'案件台帳'!$E$6:$E$65,"<="&$B$7)-COUNTIFS('案件台帳'!$C$6:$C$65,$A14,'案件台帳'!$E$6:$E$65,"<="&$B$7,'案件台帳'!$F$6:$F$65,">0")+COUNTIFS('案件台帳'!$C$6:$C$65,$A14,'案件台帳'!$E$6:$E$65,"",'案件台帳'!$F$6:$F$65,">="&$B$5)) | G14: =IF(OR($A14="",$E14=""),"",IF($E14+$F14=0,"—",IFERROR(INDEX('案件台帳'!$B$6:$B$65,SUMPRODUCT(MAX(('案件台帳'!$C$6:$C$65=$A14)*('案件台帳'!$E$6:$E$65<=$B$7)*(('案件台帳'!$F$6:$F$65>=$B$5)+('案件台帳'!$F$6:$F$65=""))*ROW('案件台帳'!$C$6:$C$65)))-5),""))) | H14: =IF($A14="","",IF($D14="空き",$B$5,IF(SUMIFS('案件台帳'!$F$6:$F$65,'案件台帳'!$C$6:$C$65,$A14,'案件台帳'!$E$6:$E$65,"<="&$B$5,'案件台帳'!$F$6:$F$65,">="&$B$5)=0,"",SUMIFS('案件台帳'!$F$6:$F$65,'案件台帳'!$C$6:$C$65,$A14,'案件台帳'!$E$6:$E$65,"<="&$B$5,'案件台帳'!$F$6:$F$65,">="&$B$5)+1))) | I14: =IF(OR($A14="",$H14=""),"",MAX(0,$H14-$B$5)) | J14: =IF($A14="","",IFERROR(INDEX(職人ダッシュボード!$M$5:$M$14,MATCH($A14,職人ダッシュボード!$A$5:$A$14,0)),"")) | K14: =IF(OR($A14="",$E14=""),"",IF($E14>0,IF(AND($D14="稼働中",ISNUMBER($I14),$I14<=7),MAX(0,60-$I14*2),0),IF($F14>0,70,100))+IF(ISNUMBER($J14),MIN(MAX($J14,0),30),0))
A15: =IF(職人ダッシュボード!$A$10="","",職人ダッシュボード!$A$10) | B15: =IF(OR($A15="",$E15=""),"",IF($E15>0,IF(AND($D15="稼働中",ISNUMBER($I15),$I15<=7),"△ "&$I15&"日ずらせば可","× 期間が重複"),IF($F15>0,"▲ 要確認（終了日未入力の案件あり）","◎ そのまま配置可"))) | C15: =IF(OR($A15="",$K15=""),"",RANK($K15,$K$10:$K$19)) | D15: =IF($A15="","",IF(COUNTIFS('案件台帳'!$C$6:$C$65,$A15,'案件台帳'!$E$6:$E$65,"<="&$B$5,'案件台帳'!$F$6:$F$65,">="&$B$5)>0,"稼働中","空き")) | E15: =IF(OR($A15="",$B$7=""),"",COUNTIFS('案件台帳'!$C$6:$C$65,$A15,'案件台帳'!$E$6:$E$65,"<="&$B$7,'案件台帳'!$F$6:$F$65,">="&$B$5)) | F15: =IF(OR($A15="",$B$7=""),"",COUNTIFS('案件台帳'!$C$6:$C$65,$A15,'案件台帳'!$E$6:$E$65,"<="&$B$7)-COUNTIFS('案件台帳'!$C$6:$C$65,$A15,'案件台帳'!$E$6:$E$65,"<="&$B$7,'案件台帳'!$F$6:$F$65,">0")+COUNTIFS('案件台帳'!$C$6:$C$65,$A15,'案件台帳'!$E$6:$E$65,"",'案件台帳'!$F$6:$F$65,">="&$B$5)) | G15: =IF(OR($A15="",$E15=""),"",IF($E15+$F15=0,"—",IFERROR(INDEX('案件台帳'!$B$6:$B$65,SUMPRODUCT(MAX(('案件台帳'!$C$6:$C$65=$A15)*('案件台帳'!$E$6:$E$65<=$B$7)*(('案件台帳'!$F$6:$F$65>=$B$5)+('案件台帳'!$F$6:$F$65=""))*ROW('案件台帳'!$C$6:$C$65)))-5),""))) | H15: =IF($A15="","",IF($D15="空き",$B$5,IF(SUMIFS('案件台帳'!$F$6:$F$65,'案件台帳'!$C$6:$C$65,$A15,'案件台帳'!$E$6:$E$65,"<="&$B$5,'案件台帳'!$F$6:$F$65,">="&$B$5)=0,"",SUMIFS('案件台帳'!$F$6:$F$65,'案件台帳'!$C$6:$C$65,$A15,'案件台帳'!$E$6:$E$65,"<="&$B$5,'案件台帳'!$F$6:$F$65,">="&$B$5)+1))) | I15: =IF(OR($A15="",$H15=""),"",MAX(0,$H15-$B$5)) | J15: =IF($A15="","",IFERROR(INDEX(職人ダッシュボード!$M$5:$M$14,MATCH($A15,職人ダッシュボード!$A$5:$A$14,0)),"")) | K15: =IF(OR($A15="",$E15=""),"",IF($E15>0,IF(AND($D15="稼働中",ISNUMBER($I15),$I15<=7),MAX(0,60-$I15*2),0),IF($F15>0,70,100))+IF(ISNUMBER($J15),MIN(MAX($J15,0),30),0))
A16: =IF(職人ダッシュボード!$A$11="","",職人ダッシュボード!$A$11) | B16: =IF(OR($A16="",$E16=""),"",IF($E16>0,IF(AND($D16="稼働中",ISNUMBER($I16),$I16<=7),"△ "&$I16&"日ずらせば可","× 期間が重複"),IF($F16>0,"▲ 要確認（終了日未入力の案件あり）","◎ そのまま配置可"))) | C16: =IF(OR($A16="",$K16=""),"",RANK($K16,$K$10:$K$19)) | D16: =IF($A16="","",IF(COUNTIFS('案件台帳'!$C$6:$C$65,$A16,'案件台帳'!$E$6:$E$65,"<="&$B$5,'案件台帳'!$F$6:$F$65,">="&$B$5)>0,"稼働中","空き")) | E16: =IF(OR($A16="",$B$7=""),"",COUNTIFS('案件台帳'!$C$6:$C$65,$A16,'案件台帳'!$E$6:$E$65,"<="&$B$7,'案件台帳'!$F$6:$F$65,">="&$B$5)) | F16: =IF(OR($A16="",$B$7=""),"",COUNTIFS('案件台帳'!$C$6:$C$65,$A16,'案件台帳'!$E$6:$E$65,"<="&$B$7)-COUNTIFS('案件台帳'!$C$6:$C$65,$A16,'案件台帳'!$E$6:$E$65,"<="&$B$7,'案件台帳'!$F$6:$F$65,">0")+COUNTIFS('案件台帳'!$C$6:$C$65,$A16,'案件台帳'!$E$6:$E$65,"",'案件台帳'!$F$6:$F$65,">="&$B$5)) | G16: =IF(OR($A16="",$E16=""),"",IF($E16+$F16=0,"—",IFERROR(INDEX('案件台帳'!$B$6:$B$65,SUMPRODUCT(MAX(('案件台帳'!$C$6:$C$65=$A16)*('案件台帳'!$E$6:$E$65<=$B$7)*(('案件台帳'!$F$6:$F$65>=$B$5)+('案件台帳'!$F$6:$F$65=""))*ROW('案件台帳'!$C$6:$C$65)))-5),""))) | H16: =IF($A16="","",IF($D16="空き",$B$5,IF(SUMIFS('案件台帳'!$F$6:$F$65,'案件台帳'!$C$6:$C$65,$A16,'案件台帳'!$E$6:$E$65,"<="&$B$5,'案件台帳'!$F$6:$F$65,">="&$B$5)=0,"",SUMIFS('案件台帳'!$F$6:$F$65,'案件台帳'!$C$6:$C$65,$A16,'案件台帳'!$E$6:$E$65,"<="&$B$5,'案件台帳'!$F$6:$F$65,">="&$B$5)+1))) | I16: =IF(OR($A16="",$H16=""),"",MAX(0,$H16-$B$5)) | J16: =IF($A16="","",IFERROR(INDEX(職人ダッシュボード!$M$5:$M$14,MATCH($A16,職人ダッシュボード!$A$5:$A$14,0)),"")) | K16: =IF(OR($A16="",$E16=""),"",IF($E16>0,IF(AND($D16="稼働中",ISNUMBER($I16),$I16<=7),MAX(0,60-$I16*2),0),IF($F16>0,70,100))+IF(ISNUMBER($J16),MIN(MAX($J16,0),30),0))
A17: =IF(職人ダッシュボード!$A$12="","",職人ダッシュボード!$A$12) | B17: =IF(OR($A17="",$E17=""),"",IF($E17>0,IF(AND($D17="稼働中",ISNUMBER($I17),$I17<=7),"△ "&$I17&"日ずらせば可","× 期間が重複"),IF($F17>0,"▲ 要確認（終了日未入力の案件あり）","◎ そのまま配置可"))) | C17: =IF(OR($A17="",$K17=""),"",RANK($K17,$K$10:$K$19)) | D17: =IF($A17="","",IF(COUNTIFS('案件台帳'!$C$6:$C$65,$A17,'案件台帳'!$E$6:$E$65,"<="&$B$5,'案件台帳'!$F$6:$F$65,">="&$B$5)>0,"稼働中","空き")) | E17: =IF(OR($A17="",$B$7=""),"",COUNTIFS('案件台帳'!$C$6:$C$65,$A17,'案件台帳'!$E$6:$E$65,"<="&$B$7,'案件台帳'!$F$6:$F$65,">="&$B$5)) | F17: =IF(OR($A17="",$B$7=""),"",COUNTIFS('案件台帳'!$C$6:$C$65,$A17,'案件台帳'!$E$6:$E$65,"<="&$B$7)-COUNTIFS('案件台帳'!$C$6:$C$65,$A17,'案件台帳'!$E$6:$E$65,"<="&$B$7,'案件台帳'!$F$6:$F$65,">0")+COUNTIFS('案件台帳'!$C$6:$C$65,$A17,'案件台帳'!$E$6:$E$65,"",'案件台帳'!$F$6:$F$65,">="&$B$5)) | G17: =IF(OR($A17="",$E17=""),"",IF($E17+$F17=0,"—",IFERROR(INDEX('案件台帳'!$B$6:$B$65,SUMPRODUCT(MAX(('案件台帳'!$C$6:$C$65=$A17)*('案件台帳'!$E$6:$E$65<=$B$7)*(('案件台帳'!$F$6:$F$65>=$B$5)+('案件台帳'!$F$6:$F$65=""))*ROW('案件台帳'!$C$6:$C$65)))-5),""))) | H17: =IF($A17="","",IF($D17="空き",$B$5,IF(SUMIFS('案件台帳'!$F$6:$F$65,'案件台帳'!$C$6:$C$65,$A17,'案件台帳'!$E$6:$E$65,"<="&$B$5,'案件台帳'!$F$6:$F$65,">="&$B$5)=0,"",SUMIFS('案件台帳'!$F$6:$F$65,'案件台帳'!$C$6:$C$65,$A17,'案件台帳'!$E$6:$E$65,"<="&$B$5,'案件台帳'!$F$6:$F$65,">="&$B$5)+1))) | I17: =IF(OR($A17="",$H17=""),"",MAX(0,$H17-$B$5)) | J17: =IF($A17="","",IFERROR(INDEX(職人ダッシュボード!$M$5:$M$14,MATCH($A17,職人ダッシュボード!$A$5:$A$14,0)),"")) | K17: =IF(OR($A17="",$E17=""),"",IF($E17>0,IF(AND($D17="稼働中",ISNUMBER($I17),$I17<=7),MAX(0,60-$I17*2),0),IF($F17>0,70,100))+IF(ISNUMBER($J17),MIN(MAX($J17,0),30),0))
A18: =IF(職人ダッシュボード!$A$13="","",職人ダッシュボード!$A$13) | B18: =IF(OR($A18="",$E18=""),"",IF($E18>0,IF(AND($D18="稼働中",ISNUMBER($I18),$I18<=7),"△ "&$I18&"日ずらせば可","× 期間が重複"),IF($F18>0,"▲ 要確認（終了日未入力の案件あり）","◎ そのまま配置可"))) | C18: =IF(OR($A18="",$K18=""),"",RANK($K18,$K$10:$K$19)) | D18: =IF($A18="","",IF(COUNTIFS('案件台帳'!$C$6:$C$65,$A18,'案件台帳'!$E$6:$E$65,"<="&$B$5,'案件台帳'!$F$6:$F$65,">="&$B$5)>0,"稼働中","空き")) | E18: =IF(OR($A18="",$B$7=""),"",COUNTIFS('案件台帳'!$C$6:$C$65,$A18,'案件台帳'!$E$6:$E$65,"<="&$B$7,'案件台帳'!$F$6:$F$65,">="&$B$5)) | F18: =IF(OR($A18="",$B$7=""),"",COUNTIFS('案件台帳'!$C$6:$C$65,$A18,'案件台帳'!$E$6:$E$65,"<="&$B$7)-COUNTIFS('案件台帳'!$C$6:$C$65,$A18,'案件台帳'!$E$6:$E$65,"<="&$B$7,'案件台帳'!$F$6:$F$65,">0")+COUNTIFS('案件台帳'!$C$6:$C$65,$A18,'案件台帳'!$E$6:$E$65,"",'案件台帳'!$F$6:$F$65,">="&$B$5)) | G18: =IF(OR($A18="",$E18=""),"",IF($E18+$F18=0,"—",IFERROR(INDEX('案件台帳'!$B$6:$B$65,SUMPRODUCT(MAX(('案件台帳'!$C$6:$C$65=$A18)*('案件台帳'!$E$6:$E$65<=$B$7)*(('案件台帳'!$F$6:$F$65>=$B$5)+('案件台帳'!$F$6:$F$65=""))*ROW('案件台帳'!$C$6:$C$65)))-5),""))) | H18: =IF($A18="","",IF($D18="空き",$B$5,IF(SUMIFS('案件台帳'!$F$6:$F$65,'案件台帳'!$C$6:$C$65,$A18,'案件台帳'!$E$6:$E$65,"<="&$B$5,'案件台帳'!$F$6:$F$65,">="&$B$5)=0,"",SUMIFS('案件台帳'!$F$6:$F$65,'案件台帳'!$C$6:$C$65,$A18,'案件台帳'!$E$6:$E$65,"<="&$B$5,'案件台帳'!$F$6:$F$65,">="&$B$5)+1))) | I18: =IF(OR($A18="",$H18=""),"",MAX(0,$H18-$B$5)) | J18: =IF($A18="","",IFERROR(INDEX(職人ダッシュボード!$M$5:$M$14,MATCH($A18,職人ダッシュボード!$A$5:$A$14,0)),"")) | K18: =IF(OR($A18="",$E18=""),"",IF($E18>0,IF(AND($D18="稼働中",ISNUMBER($I18),$I18<=7),MAX(0,60-$I18*2),0),IF($F18>0,70,100))+IF(ISNUMBER($J18),MIN(MAX($J18,0),30),0))
A19: =IF(職人ダッシュボード!$A$14="","",職人ダッシュボード!$A$14) | B19: =IF(OR($A19="",$E19=""),"",IF($E19>0,IF(AND($D19="稼働中",ISNUMBER($I19),$I19<=7),"△ "&$I19&"日ずらせば可","× 期間が重複"),IF($F19>0,"▲ 要確認（終了日未入力の案件あり）","◎ そのまま配置可"))) | C19: =IF(OR($A19="",$K19=""),"",RANK($K19,$K$10:$K$19)) | D19: =IF($A19="","",IF(COUNTIFS('案件台帳'!$C$6:$C$65,$A19,'案件台帳'!$E$6:$E$65,"<="&$B$5,'案件台帳'!$F$6:$F$65,">="&$B$5)>0,"稼働中","空き")) | E19: =IF(OR($A19="",$B$7=""),"",COUNTIFS('案件台帳'!$C$6:$C$65,$A19,'案件台帳'!$E$6:$E$65,"<="&$B$7,'案件台帳'!$F$6:$F$65,">="&$B$5)) | F19: =IF(OR($A19="",$B$7=""),"",COUNTIFS('案件台帳'!$C$6:$C$65,$A19,'案件台帳'!$E$6:$E$65,"<="&$B$7)-COUNTIFS('案件台帳'!$C$6:$C$65,$A19,'案件台帳'!$E$6:$E$65,"<="&$B$7,'案件台帳'!$F$6:$F$65,">0")+COUNTIFS('案件台帳'!$C$6:$C$65,$A19,'案件台帳'!$E$6:$E$65,"",'案件台帳'!$F$6:$F$65,">="&$B$5)) | G19: =IF(OR($A19="",$E19=""),"",IF($E19+$F19=0,"—",IFERROR(INDEX('案件台帳'!$B$6:$B$65,SUMPRODUCT(MAX(('案件台帳'!$C$6:$C$65=$A19)*('案件台帳'!$E$6:$E$65<=$B$7)*(('案件台帳'!$F$6:$F$65>=$B$5)+('案件台帳'!$F$6:$F$65=""))*ROW('案件台帳'!$C$6:$C$65)))-5),""))) | H19: =IF($A19="","",IF($D19="空き",$B$5,IF(SUMIFS('案件台帳'!$F$6:$F$65,'案件台帳'!$C$6:$C$65,$A19,'案件台帳'!$E$6:$E$65,"<="&$B$5,'案件台帳'!$F$6:$F$65,">="&$B$5)=0,"",SUMIFS('案件台帳'!$F$6:$F$65,'案件台帳'!$C$6:$C$65,$A19,'案件台帳'!$E$6:$E$65,"<="&$B$5,'案件台帳'!$F$6:$F$65,">="&$B$5)+1))) | I19: =IF(OR($A19="",$H19=""),"",MAX(0,$H19-$B$5)) | J19: =IF($A19="","",IFERROR(INDEX(職人ダッシュボード!$M$5:$M$14,MATCH($A19,職人ダッシュボード!$A$5:$A$14,0)),"")) | K19: =IF(OR($A19="",$E19=""),"",IF($E19>0,IF(AND($D19="稼働中",ISNUMBER($I19),$I19<=7),MAX(0,60-$I19*2),0),IF($F19>0,70,100))+IF(ISNUMBER($J19),MIN(MAX($J19,0),30),0))
A21: 判定の意味： ◎＝希望期間にほかの現場が1件も重ならない ／ ▲＝終了日が未入力の案件があり重なるか判定できない（台帳を埋めてから決める） ／ △＝待てば入れる（待ち日数7日以内） ／ ×＝期間が重複するので別の職人か日程変更が必要。
A22: 推奨スコア： ◎=100点／▲=70点／△=60−待ち日数×2点／×=0点。そこに「次の仕事までの空き日数」を最大30点まで加算（空きが長い職人ほど優先して埋める）。
A23: 使い方： 判定◎のなかで推奨順位1位＝いちばん手が空いている職人。ここに入れるのが段取り上いちばん無駄が少なくなります。
A24: ※ 職人の得意工種・現場までの距離・組み合わせの相性は数字に入っていません。最終判断は圭佑さんの現場感覚で。

Sheet 稼働カレンダー
A1: ④ 稼働カレンダー（基準日から63日分）
A2: ■＝現場に入っている日／空白（黄色）＝空き。案件台帳の開始日〜終了予定日から自動で塗られます。
A4: 日付 → | B4: ='案件台帳'!$B$3 | C4: =B4+1 | D4: =C4+1 | E4: =D4+1 | F4: =E4+1 | G4: =F4+1 | H4: =G4+1 | I4: =H4+1 | J4: =I4+1 | ... BL4: =BK4+1
A5: 曜日 | B5: =CHOOSE(WEEKDAY(B$4),"日","月","火","水","木","金","土") | C5: =CHOOSE(WEEKDAY(C$4),"日","月","火","水","木","金","土") | D5: =CHOOSE(WEEKDAY(D$4),"日","月","火","水","木","金","土") | E5: =CHOOSE(WEEKDAY(E$4),"日","月","火","水","木","金","土") | F5: =CHOOSE(WEEKDAY(F$4),"日","月","火","水","木","金","土") | G5: =CHOOSE(WEEKDAY(G$4),"日","月","火","水","木","金","土") | H5: =CHOOSE(WEEKDAY(H$4),"日","月","火","水","木","金","土") | I5: =CHOOSE(WEEKDAY(I$4),"日","月","火","水","木","金","土") | ... BL5: =CHOOSE(WEEKDAY(BL$4),"日","月","火","水","木","金","土")
A6: =IF(職人ダッシュボード!$A$5="","",職人ダッシュボード!$A$5) | B6: =IF($A6="","",IF(COUNTIFS('案件台帳'!$C$6:$C$65,$A6,'案件台帳'!$E$6:$E$65,"<="&B$4,'案件台帳'!$F$6:$F$65,">="&B$4)+COUNTIFS('案件台帳'!$C$6:$C$65,$A6,'案件台帳'!$E$6:$E$65,"",'案件台帳'!$F$6:$F$65,">="&B$4)>0,"■","")) | C6: =IF($A6="","",IF(COUNTIFS('案件台帳'!$C$6:$C$65,$A6,'案件台帳'!$E$6:$E$65,"<="&C$4,'案件台帳'!$F$6:$F$65,">="&C$4)+COUNTIFS('案件台帳'!$C$6:$C$65,$A6,'案件台帳'!$E$6:$E$65,"",'案件台帳'!$F$6:$F$65,">="&C$4)>0,"■","")) | D6: =IF($A6="","",IF(COUNTIFS('案件台帳'!$C$6:$C$65,$A6,'案件台帳'!$E$6:$E$65,"<="&D$4,'案件台帳'!$F$6:$F$65,">="&D$4)+COUNTIFS('案件台帳'!$C$6:$C$65,$A6,'案件台帳'!$E$6:$E$65,"",'案件台帳'!$F$6:$F$65,">="&D$4)>0,"■","")) | E6: =IF($A6="","",IF(COUNTIFS('案件台帳'!$C$6:$C$65,$A6,'案件台帳'!$E$6:$E$65,"<="&E$4,'案件台帳'!$F$6:$F$65,">="&E$4)+COUNTIFS('案件台帳'!$C$6:$C$65,$A6,'案件台帳'!$E$6:$E$65,"",'案件台帳'!$F$6:$F$65,">="&E$4)>0,"■","")) | F6: =IF($A6="","",IF(COUNTIFS('案件台帳'!$C$6:$C$65,$A6,'案件台帳'!$E$6:$E$65,"<="&F$4,'案件台帳'!$F$6:$F$65,">="&F$4)+COUNTIFS('案件台帳'!$C$6:$C$65,$A6,'案件台帳'!$E$6:$E$65,"",'案件台帳'!$F$6:$F$65,">="&F$4)>0,"■","")) | G6: =IF($A6="","",IF(COUNTIFS('案件台帳'!$C$6:$C$65,$A6,'案件台帳'!$E$6:$E$65,"<="&G$4,'案件台帳'!$F$6:$F$65,">="&G$4)+COUNTIFS('案件台帳'!$C$6:$C$65,$A6,'案件台帳'!$E$6:$E$65,"",'案件台帳'!$F$6:$F$65,">="&G$4)>0,"■","")) | H6: =IF($A6="","",IF(COUNTIFS('案件台帳'!$C$6:$C$65,$A6,'案件台帳'!$E$6:$E$65,"<="&H$4,'案件台帳'!$F$6:$F$65,">="&H$4)+COUNTIFS('案件台帳'!$C$6:$C$65,$A6,'案件台帳'!$E$6:$E$65,"",'案件台帳'!$F$6:$F$65,">="&H$4)>0,"■","")) | I6: =IF($A6="","",IF(COUNTIFS('案件台帳'!$C$6:$C$65,$A6,'案件台帳'!$E$6:$E$65,"<="&I$4,'案件台帳'!$F$6:$F$65,">="&I$4)+COUNTIFS('案件台帳'!$C$6:$C$65,$A6,'案件台帳'!$E$6:$E$65,"",'案件台帳'!$F$6:$F$65,">="&I$4)>0,"■","")) | ... BL6: =IF($A6="","",IF(COUNTIFS('案件台帳'!$C$6:$C$65,$A6,'案件台帳'!$E$6:$E$65,"<="&BL$4,'案件台帳'!$F$6:$F$65,">="&BL$4)+COUNTIFS('案件台帳'!$C$6:$C$65,$A6,'案件台帳'!$E$6:$E$65,"",'案件台帳'!$F$6:$F$65,">="&BL$4)>0,"■",""))
A7: =IF(職人ダッシュボード!$A$6="","",職人ダッシュボード!$A$6) | B7: =IF($A7="","",IF(COUNTIFS('案件台帳'!$C$6:$C$65,$A7,'案件台帳'!$E$6:$E$65,"<="&B$4,'案件台帳'!$F$6:$F$65,">="&B$4)+COUNTIFS('案件台帳'!$C$6:$C$65,$A7,'案件台帳'!$E$6:$E$65,"",'案件台帳'!$F$6:$F$65,">="&B$4)>0,"■","")) | C7: =IF($A7="","",IF(COUNTIFS('案件台帳'!$C$6:$C$65,$A7,'案件台帳'!$E$6:$E$65,"<="&C$4,'案件台帳'!$F$6:$F$65,">="&C$4)+COUNTIFS('案件台帳'!$C$6:$C$65,$A7,'案件台帳'!$E$6:$E$65,"",'案件台帳'!$F$6:$F$65,">="&C$4)>0,"■","")) | D7: =IF($A7="","",IF(COUNTIFS('案件台帳'!$C$6:$C$65,$A7,'案件台帳'!$E$6:$E$65,"<="&D$4,'案件台帳'!$F$6:$F$65,">="&D$4)+COUNTIFS('案件台帳'!$C$6:$C$65,$A7,'案件台帳'!$E$6:$E$65,"",'案件台帳'!$F$6:$F$65,">="&D$4)>0,"■","")) | E7: =IF($A7="","",IF(COUNTIFS('案件台帳'!$C$6:$C$65,$A7,'案件台帳'!$E$6:$E$65,"<="&E$4,'案件台帳'!$F$6:$F$65,">="&E$4)+COUNTIFS('案件台帳'!$C$6:$C$65,$A7,'案件台帳'!$E$6:$E$65,"",'案件台帳'!$F$6:$F$65,">="&E$4)>0,"■","")) | F7: =IF($A7="","",IF(COUNTIFS('案件台帳'!$C$6:$C$65,$A7,'案件台帳'!$E$6:$E$65,"<="&F$4,'案件台帳'!$F$6:$F$65,">="&F$4)+COUNTIFS('案件台帳'!$C$6:$C$65,$A7,'案件台帳'!$E$6:$E$65,"",'案件台帳'!$F$6:$F$65,">="&F$4)>0,"■","")) | G7: =IF($A7="","",IF(COUNTIFS('案件台帳'!$C$6:$C$65,$A7,'案件台帳'!$E$6:$E$65,"<="&G$4,'案件台帳'!$F$6:$F$65,">="&G$4)+COUNTIFS('案件台帳'!$C$6:$C$65,$A7,'案件台帳'!$E$6:$E$65,"",'案件台帳'!$F$6:$F$65,">="&G$4)>0,"■","")) | H7: =IF($A7="","",IF(COUNTIFS('案件台帳'!$C$6:$C$65,$A7,'案件台帳'!$E$6:$E$65,"<="&H$4,'案件台帳'!$F$6:$F$65,">="&H$4)+COUNTIFS('案件台帳'!$C$6:$C$65,$A7,'案件台帳'!$E$6:$E$65,"",'案件台帳'!$F$6:$F$65,">="&H$4)>0,"■","")) | I7: =IF($A7="","",IF(COUNTIFS('案件台帳'!$C$6:$C$65,$A7,'案件台帳'!$E$6:$E$65,"<="&I$4,'案件台帳'!$F$6:$F$65,">="&I$4)+COUNTIFS('案件台帳'!$C$6:$C$65,$A7,'案件台帳'!$E$6:$E$65,"",'案件台帳'!$F$6:$F$65,">="&I$4)>0,"■","")) | ... BL7: =IF($A7="","",IF(COUNTIFS('案件台帳'!$C$6:$C$65,$A7,'案件台帳'!$E$6:$E$65,"<="&BL$4,'案件台帳'!$F$6:$F$65,">="&BL$4)+COUNTIFS('案件台帳'!$C$6:$C$65,$A7,'案件台帳'!$E$6:$E$65,"",'案件台帳'!$F$6:$F$65,">="&BL$4)>0,"■",""))
